[2023-10-26T06:59:59.736+0000] {processor.py:156} INFO - Started process (PID=487) to work on /opt/airflow/dags/upload_task.py
[2023-10-26T06:59:59.738+0000] {processor.py:758} INFO - Processing file /opt/airflow/dags/upload_task.py for tasks to queue
[2023-10-26T06:59:59.740+0000] {logging_mixin.py:117} INFO - [2023-10-26T06:59:59.740+0000] {dagbag.py:525} INFO - Filling up the DagBag from /opt/airflow/dags/upload_task.py
[2023-10-26T07:00:04.790+0000] {logging_mixin.py:117} INFO - [2023-10-26T07:00:04.774+0000] {dagbag.py:330} ERROR - Failed to import: /opt/airflow/dags/upload_task.py
Traceback (most recent call last):
  File "/usr/local/lib/python3.7/site-packages/airflow/models/dagbag.py", line 326, in parse
    loader.exec_module(new_module)
  File "<frozen importlib._bootstrap_external>", line 728, in exec_module
  File "<frozen importlib._bootstrap>", line 219, in _call_with_frames_removed
  File "/opt/airflow/dags/upload_task.py", line 19, in <module>
    gcp_conn_id = ""
  File "/usr/local/lib/python3.7/site-packages/airflow/models/baseoperator.py", line 394, in apply_defaults
    raise AirflowException(f"missing keyword arguments {display}")
airflow.exceptions.AirflowException: missing keyword arguments 'drive_folder', 'local_paths'
[2023-10-26T07:00:04.794+0000] {processor.py:770} WARNING - No viable dags retrieved from /opt/airflow/dags/upload_task.py
[2023-10-26T07:00:05.339+0000] {processor.py:178} INFO - Processing /opt/airflow/dags/upload_task.py took 5.615 seconds
[2023-10-26T07:00:36.056+0000] {processor.py:156} INFO - Started process (PID=519) to work on /opt/airflow/dags/upload_task.py
[2023-10-26T07:00:39.051+0000] {processor.py:758} INFO - Processing file /opt/airflow/dags/upload_task.py for tasks to queue
[2023-10-26T07:00:42.593+0000] {logging_mixin.py:117} INFO - [2023-10-26T07:00:42.590+0000] {dagbag.py:525} INFO - Filling up the DagBag from /opt/airflow/dags/upload_task.py
[2023-10-26T07:01:00.098+0000] {logging_mixin.py:117} INFO - [2023-10-26T07:00:59.701+0000] {dagbag.py:330} ERROR - Failed to import: /opt/airflow/dags/upload_task.py
Traceback (most recent call last):
  File "/usr/local/lib/python3.7/site-packages/airflow/models/dagbag.py", line 326, in parse
    loader.exec_module(new_module)
  File "<frozen importlib._bootstrap_external>", line 728, in exec_module
  File "<frozen importlib._bootstrap>", line 219, in _call_with_frames_removed
  File "/opt/airflow/dags/upload_task.py", line 19, in <module>
    gcp_conn_id = ""
  File "/usr/local/lib/python3.7/site-packages/airflow/models/baseoperator.py", line 394, in apply_defaults
    raise AirflowException(f"missing keyword arguments {display}")
airflow.exceptions.AirflowException: missing keyword arguments 'drive_folder', 'local_paths'
[2023-10-26T07:01:00.109+0000] {processor.py:770} WARNING - No viable dags retrieved from /opt/airflow/dags/upload_task.py
[2023-10-26T07:01:10.627+0000] {processor.py:181} ERROR - Got an exception! Propagating...
Traceback (most recent call last):
  File "/usr/local/lib/python3.7/site-packages/sqlalchemy/engine/base.py", line 3371, in _wrap_pool_connect
    return fn()
  File "/usr/local/lib/python3.7/site-packages/sqlalchemy/pool/base.py", line 327, in connect
    return _ConnectionFairy._checkout(self)
  File "/usr/local/lib/python3.7/site-packages/sqlalchemy/pool/base.py", line 894, in _checkout
    fairy = _ConnectionRecord.checkout(pool)
  File "/usr/local/lib/python3.7/site-packages/sqlalchemy/pool/base.py", line 493, in checkout
    rec = pool._do_get()
  File "/usr/local/lib/python3.7/site-packages/sqlalchemy/pool/impl.py", line 146, in _do_get
    self._dec_overflow()
  File "/usr/local/lib/python3.7/site-packages/sqlalchemy/util/langhelpers.py", line 72, in __exit__
    with_traceback=exc_tb,
  File "/usr/local/lib/python3.7/site-packages/sqlalchemy/util/compat.py", line 211, in raise_
    raise exception
  File "/usr/local/lib/python3.7/site-packages/sqlalchemy/pool/impl.py", line 143, in _do_get
    return self._create_connection()
  File "/usr/local/lib/python3.7/site-packages/sqlalchemy/pool/base.py", line 273, in _create_connection
    return _ConnectionRecord(self)
  File "/usr/local/lib/python3.7/site-packages/sqlalchemy/pool/base.py", line 388, in __init__
    self.__connect()
  File "/usr/local/lib/python3.7/site-packages/sqlalchemy/pool/base.py", line 691, in __connect
    pool.logger.debug("Error on connect(): %s", e)
  File "/usr/local/lib/python3.7/site-packages/sqlalchemy/util/langhelpers.py", line 72, in __exit__
    with_traceback=exc_tb,
  File "/usr/local/lib/python3.7/site-packages/sqlalchemy/util/compat.py", line 211, in raise_
    raise exception
  File "/usr/local/lib/python3.7/site-packages/sqlalchemy/pool/base.py", line 686, in __connect
    self.dbapi_connection = connection = pool._invoke_creator(self)
  File "/usr/local/lib/python3.7/site-packages/sqlalchemy/engine/create.py", line 574, in connect
    return dialect.connect(*cargs, **cparams)
  File "/usr/local/lib/python3.7/site-packages/sqlalchemy/engine/default.py", line 598, in connect
    return self.dbapi.connect(*cargs, **cparams)
  File "/usr/local/lib/python3.7/site-packages/psycopg2/__init__.py", line 122, in connect
    conn = _connect(dsn, connection_factory=connection_factory, **kwasync)
psycopg2.OperationalError: could not translate host name "postgres" to address: Temporary failure in name resolution


The above exception was the direct cause of the following exception:

Traceback (most recent call last):
  File "/usr/local/lib/python3.7/site-packages/airflow/dag_processing/processor.py", line 177, in _run_file_processor
    _handle_dag_file_processing()
  File "/usr/local/lib/python3.7/site-packages/airflow/dag_processing/processor.py", line 161, in _handle_dag_file_processing
    callback_requests=callback_requests,
  File "/usr/local/lib/python3.7/site-packages/airflow/utils/session.py", line 75, in wrapper
    return func(*args, session=session, **kwargs)
  File "/usr/local/lib/python3.7/site-packages/airflow/dag_processing/processor.py", line 771, in process_file
    self.update_import_errors(session, dagbag)
  File "/usr/local/lib/python3.7/site-packages/airflow/dag_processing/processor.py", line 558, in update_import_errors
    existing_import_error_files = [x.filename for x in session.query(errors.ImportError.filename).all()]
  File "/usr/local/lib/python3.7/site-packages/sqlalchemy/orm/query.py", line 2773, in all
    return self._iter().all()
  File "/usr/local/lib/python3.7/site-packages/sqlalchemy/orm/query.py", line 2919, in _iter
    execution_options={"_sa_orm_load_options": self.load_options},
  File "/usr/local/lib/python3.7/site-packages/sqlalchemy/orm/session.py", line 1716, in execute
    conn = self._connection_for_bind(bind)
  File "/usr/local/lib/python3.7/site-packages/sqlalchemy/orm/session.py", line 1556, in _connection_for_bind
    engine, execution_options
  File "/usr/local/lib/python3.7/site-packages/sqlalchemy/orm/session.py", line 750, in _connection_for_bind
    conn = bind.connect()
  File "/usr/local/lib/python3.7/site-packages/sqlalchemy/engine/base.py", line 3325, in connect
    return self._connection_cls(self, close_with_result=close_with_result)
  File "/usr/local/lib/python3.7/site-packages/sqlalchemy/engine/base.py", line 96, in __init__
    else engine.raw_connection()
  File "/usr/local/lib/python3.7/site-packages/sqlalchemy/engine/base.py", line 3404, in raw_connection
    return self._wrap_pool_connect(self.pool.connect, _connection)
  File "/usr/local/lib/python3.7/site-packages/sqlalchemy/engine/base.py", line 3375, in _wrap_pool_connect
    e, dialect, self
  File "/usr/local/lib/python3.7/site-packages/sqlalchemy/engine/base.py", line 2209, in _handle_dbapi_exception_noconnection
    sqlalchemy_exception, with_traceback=exc_info[2], from_=e
  File "/usr/local/lib/python3.7/site-packages/sqlalchemy/util/compat.py", line 211, in raise_
    raise exception
  File "/usr/local/lib/python3.7/site-packages/sqlalchemy/engine/base.py", line 3371, in _wrap_pool_connect
    return fn()
  File "/usr/local/lib/python3.7/site-packages/sqlalchemy/pool/base.py", line 327, in connect
    return _ConnectionFairy._checkout(self)
  File "/usr/local/lib/python3.7/site-packages/sqlalchemy/pool/base.py", line 894, in _checkout
    fairy = _ConnectionRecord.checkout(pool)
  File "/usr/local/lib/python3.7/site-packages/sqlalchemy/pool/base.py", line 493, in checkout
    rec = pool._do_get()
  File "/usr/local/lib/python3.7/site-packages/sqlalchemy/pool/impl.py", line 146, in _do_get
    self._dec_overflow()
  File "/usr/local/lib/python3.7/site-packages/sqlalchemy/util/langhelpers.py", line 72, in __exit__
    with_traceback=exc_tb,
  File "/usr/local/lib/python3.7/site-packages/sqlalchemy/util/compat.py", line 211, in raise_
    raise exception
  File "/usr/local/lib/python3.7/site-packages/sqlalchemy/pool/impl.py", line 143, in _do_get
    return self._create_connection()
  File "/usr/local/lib/python3.7/site-packages/sqlalchemy/pool/base.py", line 273, in _create_connection
    return _ConnectionRecord(self)
  File "/usr/local/lib/python3.7/site-packages/sqlalchemy/pool/base.py", line 388, in __init__
    self.__connect()
  File "/usr/local/lib/python3.7/site-packages/sqlalchemy/pool/base.py", line 691, in __connect
    pool.logger.debug("Error on connect(): %s", e)
  File "/usr/local/lib/python3.7/site-packages/sqlalchemy/util/langhelpers.py", line 72, in __exit__
    with_traceback=exc_tb,
  File "/usr/local/lib/python3.7/site-packages/sqlalchemy/util/compat.py", line 211, in raise_
    raise exception
  File "/usr/local/lib/python3.7/site-packages/sqlalchemy/pool/base.py", line 686, in __connect
    self.dbapi_connection = connection = pool._invoke_creator(self)
  File "/usr/local/lib/python3.7/site-packages/sqlalchemy/engine/create.py", line 574, in connect
    return dialect.connect(*cargs, **cparams)
  File "/usr/local/lib/python3.7/site-packages/sqlalchemy/engine/default.py", line 598, in connect
    return self.dbapi.connect(*cargs, **cparams)
  File "/usr/local/lib/python3.7/site-packages/psycopg2/__init__.py", line 122, in connect
    conn = _connect(dsn, connection_factory=connection_factory, **kwasync)
sqlalchemy.exc.OperationalError: (psycopg2.OperationalError) could not translate host name "postgres" to address: Temporary failure in name resolution

(Background on this error at: https://sqlalche.me/e/14/e3q8)
[2023-10-26T07:02:04.085+0000] {processor.py:156} INFO - Started process (PID=541) to work on /opt/airflow/dags/upload_task.py
[2023-10-26T07:02:04.107+0000] {processor.py:758} INFO - Processing file /opt/airflow/dags/upload_task.py for tasks to queue
[2023-10-26T07:02:04.129+0000] {logging_mixin.py:117} INFO - [2023-10-26T07:02:04.128+0000] {dagbag.py:525} INFO - Filling up the DagBag from /opt/airflow/dags/upload_task.py
[2023-10-26T07:02:27.823+0000] {logging_mixin.py:117} INFO - [2023-10-26T07:02:27.794+0000] {dagbag.py:330} ERROR - Failed to import: /opt/airflow/dags/upload_task.py
Traceback (most recent call last):
  File "/usr/local/lib/python3.7/site-packages/airflow/models/dagbag.py", line 326, in parse
    loader.exec_module(new_module)
  File "<frozen importlib._bootstrap_external>", line 728, in exec_module
  File "<frozen importlib._bootstrap>", line 219, in _call_with_frames_removed
  File "/opt/airflow/dags/upload_task.py", line 19, in <module>
    gcp_conn_id = ""
  File "/usr/local/lib/python3.7/site-packages/airflow/models/baseoperator.py", line 394, in apply_defaults
    raise AirflowException(f"missing keyword arguments {display}")
airflow.exceptions.AirflowException: missing keyword arguments 'drive_folder', 'local_paths'
[2023-10-26T07:02:27.846+0000] {processor.py:770} WARNING - No viable dags retrieved from /opt/airflow/dags/upload_task.py
[2023-10-26T07:02:40.522+0000] {processor.py:181} ERROR - Got an exception! Propagating...
Traceback (most recent call last):
  File "/usr/local/lib/python3.7/site-packages/sqlalchemy/engine/base.py", line 3371, in _wrap_pool_connect
    return fn()
  File "/usr/local/lib/python3.7/site-packages/sqlalchemy/pool/base.py", line 327, in connect
    return _ConnectionFairy._checkout(self)
  File "/usr/local/lib/python3.7/site-packages/sqlalchemy/pool/base.py", line 894, in _checkout
    fairy = _ConnectionRecord.checkout(pool)
  File "/usr/local/lib/python3.7/site-packages/sqlalchemy/pool/base.py", line 493, in checkout
    rec = pool._do_get()
  File "/usr/local/lib/python3.7/site-packages/sqlalchemy/pool/impl.py", line 146, in _do_get
    self._dec_overflow()
  File "/usr/local/lib/python3.7/site-packages/sqlalchemy/util/langhelpers.py", line 72, in __exit__
    with_traceback=exc_tb,
  File "/usr/local/lib/python3.7/site-packages/sqlalchemy/util/compat.py", line 211, in raise_
    raise exception
  File "/usr/local/lib/python3.7/site-packages/sqlalchemy/pool/impl.py", line 143, in _do_get
    return self._create_connection()
  File "/usr/local/lib/python3.7/site-packages/sqlalchemy/pool/base.py", line 273, in _create_connection
    return _ConnectionRecord(self)
  File "/usr/local/lib/python3.7/site-packages/sqlalchemy/pool/base.py", line 388, in __init__
    self.__connect()
  File "/usr/local/lib/python3.7/site-packages/sqlalchemy/pool/base.py", line 691, in __connect
    pool.logger.debug("Error on connect(): %s", e)
  File "/usr/local/lib/python3.7/site-packages/sqlalchemy/util/langhelpers.py", line 72, in __exit__
    with_traceback=exc_tb,
  File "/usr/local/lib/python3.7/site-packages/sqlalchemy/util/compat.py", line 211, in raise_
    raise exception
  File "/usr/local/lib/python3.7/site-packages/sqlalchemy/pool/base.py", line 686, in __connect
    self.dbapi_connection = connection = pool._invoke_creator(self)
  File "/usr/local/lib/python3.7/site-packages/sqlalchemy/engine/create.py", line 574, in connect
    return dialect.connect(*cargs, **cparams)
  File "/usr/local/lib/python3.7/site-packages/sqlalchemy/engine/default.py", line 598, in connect
    return self.dbapi.connect(*cargs, **cparams)
  File "/usr/local/lib/python3.7/site-packages/psycopg2/__init__.py", line 122, in connect
    conn = _connect(dsn, connection_factory=connection_factory, **kwasync)
psycopg2.OperationalError: could not translate host name "postgres" to address: Temporary failure in name resolution


The above exception was the direct cause of the following exception:

Traceback (most recent call last):
  File "/usr/local/lib/python3.7/site-packages/airflow/dag_processing/processor.py", line 177, in _run_file_processor
    _handle_dag_file_processing()
  File "/usr/local/lib/python3.7/site-packages/airflow/dag_processing/processor.py", line 161, in _handle_dag_file_processing
    callback_requests=callback_requests,
  File "/usr/local/lib/python3.7/site-packages/airflow/utils/session.py", line 75, in wrapper
    return func(*args, session=session, **kwargs)
  File "/usr/local/lib/python3.7/site-packages/airflow/dag_processing/processor.py", line 771, in process_file
    self.update_import_errors(session, dagbag)
  File "/usr/local/lib/python3.7/site-packages/airflow/dag_processing/processor.py", line 558, in update_import_errors
    existing_import_error_files = [x.filename for x in session.query(errors.ImportError.filename).all()]
  File "/usr/local/lib/python3.7/site-packages/sqlalchemy/orm/query.py", line 2773, in all
    return self._iter().all()
  File "/usr/local/lib/python3.7/site-packages/sqlalchemy/orm/query.py", line 2919, in _iter
    execution_options={"_sa_orm_load_options": self.load_options},
  File "/usr/local/lib/python3.7/site-packages/sqlalchemy/orm/session.py", line 1716, in execute
    conn = self._connection_for_bind(bind)
  File "/usr/local/lib/python3.7/site-packages/sqlalchemy/orm/session.py", line 1556, in _connection_for_bind
    engine, execution_options
  File "/usr/local/lib/python3.7/site-packages/sqlalchemy/orm/session.py", line 750, in _connection_for_bind
    conn = bind.connect()
  File "/usr/local/lib/python3.7/site-packages/sqlalchemy/engine/base.py", line 3325, in connect
    return self._connection_cls(self, close_with_result=close_with_result)
  File "/usr/local/lib/python3.7/site-packages/sqlalchemy/engine/base.py", line 96, in __init__
    else engine.raw_connection()
  File "/usr/local/lib/python3.7/site-packages/sqlalchemy/engine/base.py", line 3404, in raw_connection
    return self._wrap_pool_connect(self.pool.connect, _connection)
  File "/usr/local/lib/python3.7/site-packages/sqlalchemy/engine/base.py", line 3375, in _wrap_pool_connect
    e, dialect, self
  File "/usr/local/lib/python3.7/site-packages/sqlalchemy/engine/base.py", line 2209, in _handle_dbapi_exception_noconnection
    sqlalchemy_exception, with_traceback=exc_info[2], from_=e
  File "/usr/local/lib/python3.7/site-packages/sqlalchemy/util/compat.py", line 211, in raise_
    raise exception
  File "/usr/local/lib/python3.7/site-packages/sqlalchemy/engine/base.py", line 3371, in _wrap_pool_connect
    return fn()
  File "/usr/local/lib/python3.7/site-packages/sqlalchemy/pool/base.py", line 327, in connect
    return _ConnectionFairy._checkout(self)
  File "/usr/local/lib/python3.7/site-packages/sqlalchemy/pool/base.py", line 894, in _checkout
    fairy = _ConnectionRecord.checkout(pool)
  File "/usr/local/lib/python3.7/site-packages/sqlalchemy/pool/base.py", line 493, in checkout
    rec = pool._do_get()
  File "/usr/local/lib/python3.7/site-packages/sqlalchemy/pool/impl.py", line 146, in _do_get
    self._dec_overflow()
  File "/usr/local/lib/python3.7/site-packages/sqlalchemy/util/langhelpers.py", line 72, in __exit__
    with_traceback=exc_tb,
  File "/usr/local/lib/python3.7/site-packages/sqlalchemy/util/compat.py", line 211, in raise_
    raise exception
  File "/usr/local/lib/python3.7/site-packages/sqlalchemy/pool/impl.py", line 143, in _do_get
    return self._create_connection()
  File "/usr/local/lib/python3.7/site-packages/sqlalchemy/pool/base.py", line 273, in _create_connection
    return _ConnectionRecord(self)
  File "/usr/local/lib/python3.7/site-packages/sqlalchemy/pool/base.py", line 388, in __init__
    self.__connect()
  File "/usr/local/lib/python3.7/site-packages/sqlalchemy/pool/base.py", line 691, in __connect
    pool.logger.debug("Error on connect(): %s", e)
  File "/usr/local/lib/python3.7/site-packages/sqlalchemy/util/langhelpers.py", line 72, in __exit__
    with_traceback=exc_tb,
  File "/usr/local/lib/python3.7/site-packages/sqlalchemy/util/compat.py", line 211, in raise_
    raise exception
  File "/usr/local/lib/python3.7/site-packages/sqlalchemy/pool/base.py", line 686, in __connect
    self.dbapi_connection = connection = pool._invoke_creator(self)
  File "/usr/local/lib/python3.7/site-packages/sqlalchemy/engine/create.py", line 574, in connect
    return dialect.connect(*cargs, **cparams)
  File "/usr/local/lib/python3.7/site-packages/sqlalchemy/engine/default.py", line 598, in connect
    return self.dbapi.connect(*cargs, **cparams)
  File "/usr/local/lib/python3.7/site-packages/psycopg2/__init__.py", line 122, in connect
    conn = _connect(dsn, connection_factory=connection_factory, **kwasync)
sqlalchemy.exc.OperationalError: (psycopg2.OperationalError) could not translate host name "postgres" to address: Temporary failure in name resolution

(Background on this error at: https://sqlalche.me/e/14/e3q8)
[2023-10-26T07:03:50.737+0000] {processor.py:156} INFO - Started process (PID=547) to work on /opt/airflow/dags/upload_task.py
[2023-10-26T07:03:50.745+0000] {processor.py:758} INFO - Processing file /opt/airflow/dags/upload_task.py for tasks to queue
[2023-10-26T07:03:50.750+0000] {logging_mixin.py:117} INFO - [2023-10-26T07:03:50.749+0000] {dagbag.py:525} INFO - Filling up the DagBag from /opt/airflow/dags/upload_task.py
[2023-10-26T07:04:14.969+0000] {logging_mixin.py:117} INFO - [2023-10-26T07:04:14.595+0000] {dagbag.py:330} ERROR - Failed to import: /opt/airflow/dags/upload_task.py
Traceback (most recent call last):
  File "/usr/local/lib/python3.7/site-packages/airflow/models/dagbag.py", line 326, in parse
    loader.exec_module(new_module)
  File "<frozen importlib._bootstrap_external>", line 728, in exec_module
  File "<frozen importlib._bootstrap>", line 219, in _call_with_frames_removed
  File "/opt/airflow/dags/upload_task.py", line 19, in <module>
    gcp_conn_id = ""
  File "/usr/local/lib/python3.7/site-packages/airflow/models/baseoperator.py", line 394, in apply_defaults
    raise AirflowException(f"missing keyword arguments {display}")
airflow.exceptions.AirflowException: missing keyword arguments 'drive_folder', 'local_paths'
[2023-10-26T07:04:15.446+0000] {processor.py:770} WARNING - No viable dags retrieved from /opt/airflow/dags/upload_task.py
[2023-10-26T07:04:33.909+0000] {processor.py:181} ERROR - Got an exception! Propagating...
Traceback (most recent call last):
  File "/usr/local/lib/python3.7/site-packages/sqlalchemy/engine/base.py", line 3371, in _wrap_pool_connect
    return fn()
  File "/usr/local/lib/python3.7/site-packages/sqlalchemy/pool/base.py", line 327, in connect
    return _ConnectionFairy._checkout(self)
  File "/usr/local/lib/python3.7/site-packages/sqlalchemy/pool/base.py", line 894, in _checkout
    fairy = _ConnectionRecord.checkout(pool)
  File "/usr/local/lib/python3.7/site-packages/sqlalchemy/pool/base.py", line 493, in checkout
    rec = pool._do_get()
  File "/usr/local/lib/python3.7/site-packages/sqlalchemy/pool/impl.py", line 146, in _do_get
    self._dec_overflow()
  File "/usr/local/lib/python3.7/site-packages/sqlalchemy/util/langhelpers.py", line 72, in __exit__
    with_traceback=exc_tb,
  File "/usr/local/lib/python3.7/site-packages/sqlalchemy/util/compat.py", line 211, in raise_
    raise exception
  File "/usr/local/lib/python3.7/site-packages/sqlalchemy/pool/impl.py", line 143, in _do_get
    return self._create_connection()
  File "/usr/local/lib/python3.7/site-packages/sqlalchemy/pool/base.py", line 273, in _create_connection
    return _ConnectionRecord(self)
  File "/usr/local/lib/python3.7/site-packages/sqlalchemy/pool/base.py", line 388, in __init__
    self.__connect()
  File "/usr/local/lib/python3.7/site-packages/sqlalchemy/pool/base.py", line 691, in __connect
    pool.logger.debug("Error on connect(): %s", e)
  File "/usr/local/lib/python3.7/site-packages/sqlalchemy/util/langhelpers.py", line 72, in __exit__
    with_traceback=exc_tb,
  File "/usr/local/lib/python3.7/site-packages/sqlalchemy/util/compat.py", line 211, in raise_
    raise exception
  File "/usr/local/lib/python3.7/site-packages/sqlalchemy/pool/base.py", line 686, in __connect
    self.dbapi_connection = connection = pool._invoke_creator(self)
  File "/usr/local/lib/python3.7/site-packages/sqlalchemy/engine/create.py", line 574, in connect
    return dialect.connect(*cargs, **cparams)
  File "/usr/local/lib/python3.7/site-packages/sqlalchemy/engine/default.py", line 598, in connect
    return self.dbapi.connect(*cargs, **cparams)
  File "/usr/local/lib/python3.7/site-packages/psycopg2/__init__.py", line 122, in connect
    conn = _connect(dsn, connection_factory=connection_factory, **kwasync)
psycopg2.OperationalError: could not translate host name "postgres" to address: Temporary failure in name resolution


The above exception was the direct cause of the following exception:

Traceback (most recent call last):
  File "/usr/local/lib/python3.7/site-packages/airflow/dag_processing/processor.py", line 177, in _run_file_processor
    _handle_dag_file_processing()
  File "/usr/local/lib/python3.7/site-packages/airflow/dag_processing/processor.py", line 161, in _handle_dag_file_processing
    callback_requests=callback_requests,
  File "/usr/local/lib/python3.7/site-packages/airflow/utils/session.py", line 75, in wrapper
    return func(*args, session=session, **kwargs)
  File "/usr/local/lib/python3.7/site-packages/airflow/dag_processing/processor.py", line 771, in process_file
    self.update_import_errors(session, dagbag)
  File "/usr/local/lib/python3.7/site-packages/airflow/dag_processing/processor.py", line 558, in update_import_errors
    existing_import_error_files = [x.filename for x in session.query(errors.ImportError.filename).all()]
  File "/usr/local/lib/python3.7/site-packages/sqlalchemy/orm/query.py", line 2773, in all
    return self._iter().all()
  File "/usr/local/lib/python3.7/site-packages/sqlalchemy/orm/query.py", line 2919, in _iter
    execution_options={"_sa_orm_load_options": self.load_options},
  File "/usr/local/lib/python3.7/site-packages/sqlalchemy/orm/session.py", line 1716, in execute
    conn = self._connection_for_bind(bind)
  File "/usr/local/lib/python3.7/site-packages/sqlalchemy/orm/session.py", line 1556, in _connection_for_bind
    engine, execution_options
  File "/usr/local/lib/python3.7/site-packages/sqlalchemy/orm/session.py", line 750, in _connection_for_bind
    conn = bind.connect()
  File "/usr/local/lib/python3.7/site-packages/sqlalchemy/engine/base.py", line 3325, in connect
    return self._connection_cls(self, close_with_result=close_with_result)
  File "/usr/local/lib/python3.7/site-packages/sqlalchemy/engine/base.py", line 96, in __init__
    else engine.raw_connection()
  File "/usr/local/lib/python3.7/site-packages/sqlalchemy/engine/base.py", line 3404, in raw_connection
    return self._wrap_pool_connect(self.pool.connect, _connection)
  File "/usr/local/lib/python3.7/site-packages/sqlalchemy/engine/base.py", line 3375, in _wrap_pool_connect
    e, dialect, self
  File "/usr/local/lib/python3.7/site-packages/sqlalchemy/engine/base.py", line 2209, in _handle_dbapi_exception_noconnection
    sqlalchemy_exception, with_traceback=exc_info[2], from_=e
  File "/usr/local/lib/python3.7/site-packages/sqlalchemy/util/compat.py", line 211, in raise_
    raise exception
  File "/usr/local/lib/python3.7/site-packages/sqlalchemy/engine/base.py", line 3371, in _wrap_pool_connect
    return fn()
  File "/usr/local/lib/python3.7/site-packages/sqlalchemy/pool/base.py", line 327, in connect
    return _ConnectionFairy._checkout(self)
  File "/usr/local/lib/python3.7/site-packages/sqlalchemy/pool/base.py", line 894, in _checkout
    fairy = _ConnectionRecord.checkout(pool)
  File "/usr/local/lib/python3.7/site-packages/sqlalchemy/pool/base.py", line 493, in checkout
    rec = pool._do_get()
  File "/usr/local/lib/python3.7/site-packages/sqlalchemy/pool/impl.py", line 146, in _do_get
    self._dec_overflow()
  File "/usr/local/lib/python3.7/site-packages/sqlalchemy/util/langhelpers.py", line 72, in __exit__
    with_traceback=exc_tb,
  File "/usr/local/lib/python3.7/site-packages/sqlalchemy/util/compat.py", line 211, in raise_
    raise exception
  File "/usr/local/lib/python3.7/site-packages/sqlalchemy/pool/impl.py", line 143, in _do_get
    return self._create_connection()
  File "/usr/local/lib/python3.7/site-packages/sqlalchemy/pool/base.py", line 273, in _create_connection
    return _ConnectionRecord(self)
  File "/usr/local/lib/python3.7/site-packages/sqlalchemy/pool/base.py", line 388, in __init__
    self.__connect()
  File "/usr/local/lib/python3.7/site-packages/sqlalchemy/pool/base.py", line 691, in __connect
    pool.logger.debug("Error on connect(): %s", e)
  File "/usr/local/lib/python3.7/site-packages/sqlalchemy/util/langhelpers.py", line 72, in __exit__
    with_traceback=exc_tb,
  File "/usr/local/lib/python3.7/site-packages/sqlalchemy/util/compat.py", line 211, in raise_
    raise exception
  File "/usr/local/lib/python3.7/site-packages/sqlalchemy/pool/base.py", line 686, in __connect
    self.dbapi_connection = connection = pool._invoke_creator(self)
  File "/usr/local/lib/python3.7/site-packages/sqlalchemy/engine/create.py", line 574, in connect
    return dialect.connect(*cargs, **cparams)
  File "/usr/local/lib/python3.7/site-packages/sqlalchemy/engine/default.py", line 598, in connect
    return self.dbapi.connect(*cargs, **cparams)
  File "/usr/local/lib/python3.7/site-packages/psycopg2/__init__.py", line 122, in connect
    conn = _connect(dsn, connection_factory=connection_factory, **kwasync)
sqlalchemy.exc.OperationalError: (psycopg2.OperationalError) could not translate host name "postgres" to address: Temporary failure in name resolution

(Background on this error at: https://sqlalche.me/e/14/e3q8)
[2023-10-26T07:04:50.992+0000] {processor.py:156} INFO - Started process (PID=568) to work on /opt/airflow/dags/upload_task.py
[2023-10-26T07:04:50.996+0000] {processor.py:758} INFO - Processing file /opt/airflow/dags/upload_task.py for tasks to queue
[2023-10-26T07:04:51.006+0000] {logging_mixin.py:117} INFO - [2023-10-26T07:04:51.003+0000] {dagbag.py:525} INFO - Filling up the DagBag from /opt/airflow/dags/upload_task.py
[2023-10-26T07:05:23.389+0000] {logging_mixin.py:117} INFO - [2023-10-26T07:05:23.373+0000] {timeout.py:68} ERROR - Process timed out, PID: 568
[2023-10-26T07:05:23.517+0000] {logging_mixin.py:117} INFO - [2023-10-26T07:05:23.395+0000] {dagbag.py:330} ERROR - Failed to import: /opt/airflow/dags/upload_task.py
Traceback (most recent call last):
  File "/usr/local/lib/python3.7/site-packages/airflow/models/dagbag.py", line 326, in parse
    loader.exec_module(new_module)
  File "<frozen importlib._bootstrap_external>", line 728, in exec_module
  File "<frozen importlib._bootstrap>", line 219, in _call_with_frames_removed
  File "/opt/airflow/dags/upload_task.py", line 1, in <module>
    from airflow.providers.google.suite.transfers.local_to_drive import LocalFilesystemToGoogleDriveOperator
  File "/usr/local/lib/python3.7/site-packages/airflow/providers/google/suite/transfers/local_to_drive.py", line 26, in <module>
    from airflow.providers.google.suite.hooks.drive import GoogleDriveHook
  File "/usr/local/lib/python3.7/site-packages/airflow/providers/google/suite/hooks/drive.py", line 27, in <module>
    from airflow.providers.google.common.hooks.base_google import GoogleBaseHook
  File "/usr/local/lib/python3.7/site-packages/airflow/providers/google/common/hooks/base_google.py", line 36, in <module>
    import tenacity
  File "/usr/local/lib/python3.7/site-packages/tenacity/__init__.py", line 549, in <module>
    from tenacity.tornadoweb import TornadoRetrying
  File "/usr/local/lib/python3.7/site-packages/tenacity/tornadoweb.py", line 23, in <module>
    from tornado import gen
  File "/usr/local/lib/python3.7/site-packages/tornado/gen.py", line 81, in <module>
    from tornado.concurrent import (
  File "/usr/local/lib/python3.7/site-packages/tornado/concurrent.py", line 34, in <module>
    from tornado.log import app_log
  File "/usr/local/lib/python3.7/site-packages/tornado/log.py", line 43, in <module>
    import curses
  File "/usr/local/lib/python3.7/curses/__init__.py", line 13, in <module>
    from _curses import *
  File "/usr/local/lib/python3.7/site-packages/airflow/utils/timeout.py", line 69, in handle_timeout
    raise AirflowTaskTimeout(self.error_message)
airflow.exceptions.AirflowTaskTimeout: DagBag import timeout for /opt/airflow/dags/upload_task.py after 30.0s.
Please take a look at these docs to improve your DAG import time:
* https://airflow.apache.org/docs/apache-airflow/2.4.0/best-practices.html#top-level-python-code
* https://airflow.apache.org/docs/apache-airflow/2.4.0/best-practices.html#reducing-dag-complexity, PID: 568
[2023-10-26T07:05:23.520+0000] {processor.py:770} WARNING - No viable dags retrieved from /opt/airflow/dags/upload_task.py
[2023-10-26T07:05:33.556+0000] {processor.py:181} ERROR - Got an exception! Propagating...
Traceback (most recent call last):
  File "/usr/local/lib/python3.7/site-packages/sqlalchemy/engine/base.py", line 3371, in _wrap_pool_connect
    return fn()
  File "/usr/local/lib/python3.7/site-packages/sqlalchemy/pool/base.py", line 327, in connect
    return _ConnectionFairy._checkout(self)
  File "/usr/local/lib/python3.7/site-packages/sqlalchemy/pool/base.py", line 894, in _checkout
    fairy = _ConnectionRecord.checkout(pool)
  File "/usr/local/lib/python3.7/site-packages/sqlalchemy/pool/base.py", line 493, in checkout
    rec = pool._do_get()
  File "/usr/local/lib/python3.7/site-packages/sqlalchemy/pool/impl.py", line 146, in _do_get
    self._dec_overflow()
  File "/usr/local/lib/python3.7/site-packages/sqlalchemy/util/langhelpers.py", line 72, in __exit__
    with_traceback=exc_tb,
  File "/usr/local/lib/python3.7/site-packages/sqlalchemy/util/compat.py", line 211, in raise_
    raise exception
  File "/usr/local/lib/python3.7/site-packages/sqlalchemy/pool/impl.py", line 143, in _do_get
    return self._create_connection()
  File "/usr/local/lib/python3.7/site-packages/sqlalchemy/pool/base.py", line 273, in _create_connection
    return _ConnectionRecord(self)
  File "/usr/local/lib/python3.7/site-packages/sqlalchemy/pool/base.py", line 388, in __init__
    self.__connect()
  File "/usr/local/lib/python3.7/site-packages/sqlalchemy/pool/base.py", line 691, in __connect
    pool.logger.debug("Error on connect(): %s", e)
  File "/usr/local/lib/python3.7/site-packages/sqlalchemy/util/langhelpers.py", line 72, in __exit__
    with_traceback=exc_tb,
  File "/usr/local/lib/python3.7/site-packages/sqlalchemy/util/compat.py", line 211, in raise_
    raise exception
  File "/usr/local/lib/python3.7/site-packages/sqlalchemy/pool/base.py", line 686, in __connect
    self.dbapi_connection = connection = pool._invoke_creator(self)
  File "/usr/local/lib/python3.7/site-packages/sqlalchemy/engine/create.py", line 574, in connect
    return dialect.connect(*cargs, **cparams)
  File "/usr/local/lib/python3.7/site-packages/sqlalchemy/engine/default.py", line 598, in connect
    return self.dbapi.connect(*cargs, **cparams)
  File "/usr/local/lib/python3.7/site-packages/psycopg2/__init__.py", line 122, in connect
    conn = _connect(dsn, connection_factory=connection_factory, **kwasync)
psycopg2.OperationalError: could not translate host name "postgres" to address: Temporary failure in name resolution


The above exception was the direct cause of the following exception:

Traceback (most recent call last):
  File "/usr/local/lib/python3.7/site-packages/airflow/dag_processing/processor.py", line 177, in _run_file_processor
    _handle_dag_file_processing()
  File "/usr/local/lib/python3.7/site-packages/airflow/dag_processing/processor.py", line 161, in _handle_dag_file_processing
    callback_requests=callback_requests,
  File "/usr/local/lib/python3.7/site-packages/airflow/utils/session.py", line 75, in wrapper
    return func(*args, session=session, **kwargs)
  File "/usr/local/lib/python3.7/site-packages/airflow/dag_processing/processor.py", line 771, in process_file
    self.update_import_errors(session, dagbag)
  File "/usr/local/lib/python3.7/site-packages/airflow/dag_processing/processor.py", line 558, in update_import_errors
    existing_import_error_files = [x.filename for x in session.query(errors.ImportError.filename).all()]
  File "/usr/local/lib/python3.7/site-packages/sqlalchemy/orm/query.py", line 2773, in all
    return self._iter().all()
  File "/usr/local/lib/python3.7/site-packages/sqlalchemy/orm/query.py", line 2919, in _iter
    execution_options={"_sa_orm_load_options": self.load_options},
  File "/usr/local/lib/python3.7/site-packages/sqlalchemy/orm/session.py", line 1716, in execute
    conn = self._connection_for_bind(bind)
  File "/usr/local/lib/python3.7/site-packages/sqlalchemy/orm/session.py", line 1556, in _connection_for_bind
    engine, execution_options
  File "/usr/local/lib/python3.7/site-packages/sqlalchemy/orm/session.py", line 750, in _connection_for_bind
    conn = bind.connect()
  File "/usr/local/lib/python3.7/site-packages/sqlalchemy/engine/base.py", line 3325, in connect
    return self._connection_cls(self, close_with_result=close_with_result)
  File "/usr/local/lib/python3.7/site-packages/sqlalchemy/engine/base.py", line 96, in __init__
    else engine.raw_connection()
  File "/usr/local/lib/python3.7/site-packages/sqlalchemy/engine/base.py", line 3404, in raw_connection
    return self._wrap_pool_connect(self.pool.connect, _connection)
  File "/usr/local/lib/python3.7/site-packages/sqlalchemy/engine/base.py", line 3375, in _wrap_pool_connect
    e, dialect, self
  File "/usr/local/lib/python3.7/site-packages/sqlalchemy/engine/base.py", line 2209, in _handle_dbapi_exception_noconnection
    sqlalchemy_exception, with_traceback=exc_info[2], from_=e
  File "/usr/local/lib/python3.7/site-packages/sqlalchemy/util/compat.py", line 211, in raise_
    raise exception
  File "/usr/local/lib/python3.7/site-packages/sqlalchemy/engine/base.py", line 3371, in _wrap_pool_connect
    return fn()
  File "/usr/local/lib/python3.7/site-packages/sqlalchemy/pool/base.py", line 327, in connect
    return _ConnectionFairy._checkout(self)
  File "/usr/local/lib/python3.7/site-packages/sqlalchemy/pool/base.py", line 894, in _checkout
    fairy = _ConnectionRecord.checkout(pool)
  File "/usr/local/lib/python3.7/site-packages/sqlalchemy/pool/base.py", line 493, in checkout
    rec = pool._do_get()
  File "/usr/local/lib/python3.7/site-packages/sqlalchemy/pool/impl.py", line 146, in _do_get
    self._dec_overflow()
  File "/usr/local/lib/python3.7/site-packages/sqlalchemy/util/langhelpers.py", line 72, in __exit__
    with_traceback=exc_tb,
  File "/usr/local/lib/python3.7/site-packages/sqlalchemy/util/compat.py", line 211, in raise_
    raise exception
  File "/usr/local/lib/python3.7/site-packages/sqlalchemy/pool/impl.py", line 143, in _do_get
    return self._create_connection()
  File "/usr/local/lib/python3.7/site-packages/sqlalchemy/pool/base.py", line 273, in _create_connection
    return _ConnectionRecord(self)
  File "/usr/local/lib/python3.7/site-packages/sqlalchemy/pool/base.py", line 388, in __init__
    self.__connect()
  File "/usr/local/lib/python3.7/site-packages/sqlalchemy/pool/base.py", line 691, in __connect
    pool.logger.debug("Error on connect(): %s", e)
  File "/usr/local/lib/python3.7/site-packages/sqlalchemy/util/langhelpers.py", line 72, in __exit__
    with_traceback=exc_tb,
  File "/usr/local/lib/python3.7/site-packages/sqlalchemy/util/compat.py", line 211, in raise_
    raise exception
  File "/usr/local/lib/python3.7/site-packages/sqlalchemy/pool/base.py", line 686, in __connect
    self.dbapi_connection = connection = pool._invoke_creator(self)
  File "/usr/local/lib/python3.7/site-packages/sqlalchemy/engine/create.py", line 574, in connect
    return dialect.connect(*cargs, **cparams)
  File "/usr/local/lib/python3.7/site-packages/sqlalchemy/engine/default.py", line 598, in connect
    return self.dbapi.connect(*cargs, **cparams)
  File "/usr/local/lib/python3.7/site-packages/psycopg2/__init__.py", line 122, in connect
    conn = _connect(dsn, connection_factory=connection_factory, **kwasync)
sqlalchemy.exc.OperationalError: (psycopg2.OperationalError) could not translate host name "postgres" to address: Temporary failure in name resolution

(Background on this error at: https://sqlalche.me/e/14/e3q8)
[2023-10-26T07:06:59.626+0000] {processor.py:156} INFO - Started process (PID=592) to work on /opt/airflow/dags/upload_task.py
[2023-10-26T07:06:59.629+0000] {processor.py:758} INFO - Processing file /opt/airflow/dags/upload_task.py for tasks to queue
[2023-10-26T07:06:59.632+0000] {logging_mixin.py:117} INFO - [2023-10-26T07:06:59.631+0000] {dagbag.py:525} INFO - Filling up the DagBag from /opt/airflow/dags/upload_task.py
[2023-10-26T07:07:29.966+0000] {logging_mixin.py:117} INFO - [2023-10-26T07:07:29.840+0000] {timeout.py:68} ERROR - Process timed out, PID: 592
[2023-10-26T07:07:35.356+0000] {logging_mixin.py:117} INFO - [2023-10-26T07:07:30.235+0000] {dagbag.py:330} ERROR - Failed to import: /opt/airflow/dags/upload_task.py
Traceback (most recent call last):
  File "/usr/local/lib/python3.7/site-packages/airflow/models/dagbag.py", line 326, in parse
    loader.exec_module(new_module)
  File "<frozen importlib._bootstrap_external>", line 728, in exec_module
  File "<frozen importlib._bootstrap>", line 219, in _call_with_frames_removed
  File "/opt/airflow/dags/upload_task.py", line 1, in <module>
    from airflow.providers.google.suite.transfers.local_to_drive import LocalFilesystemToGoogleDriveOperator
  File "/usr/local/lib/python3.7/site-packages/airflow/providers/google/suite/transfers/local_to_drive.py", line 26, in <module>
    from airflow.providers.google.suite.hooks.drive import GoogleDriveHook
  File "/usr/local/lib/python3.7/site-packages/airflow/providers/google/suite/hooks/drive.py", line 27, in <module>
    from airflow.providers.google.common.hooks.base_google import GoogleBaseHook
  File "/usr/local/lib/python3.7/site-packages/airflow/providers/google/common/hooks/base_google.py", line 51, in <module>
    from airflow.providers.google.cloud.utils.credentials_provider import (
  File "/usr/local/lib/python3.7/site-packages/airflow/providers/google/cloud/utils/credentials_provider.py", line 38, in <module>
    from airflow.providers.google.cloud._internal_client.secret_manager_client import _SecretManagerClient
  File "/usr/local/lib/python3.7/site-packages/airflow/providers/google/cloud/_internal_client/secret_manager_client.py", line 23, in <module>
    from google.cloud.secretmanager_v1 import SecretManagerServiceClient
  File "/usr/local/lib/python3.7/site-packages/google/cloud/secretmanager_v1/__init__.py", line 21, in <module>
    from .services.secret_manager_service import (
  File "/usr/local/lib/python3.7/site-packages/google/cloud/secretmanager_v1/services/secret_manager_service/__init__.py", line 16, in <module>
    from .async_client import SecretManagerServiceAsyncClient
  File "/usr/local/lib/python3.7/site-packages/google/cloud/secretmanager_v1/services/secret_manager_service/async_client.py", line 51, in <module>
    from google.cloud.secretmanager_v1.services.secret_manager_service import pagers
  File "/usr/local/lib/python3.7/site-packages/google/cloud/secretmanager_v1/services/secret_manager_service/pagers.py", line 27, in <module>
    from google.cloud.secretmanager_v1.types import resources, service
  File "/usr/local/lib/python3.7/site-packages/google/cloud/secretmanager_v1/types/__init__.py", line 16, in <module>
    from .resources import (
  File "/usr/local/lib/python3.7/site-packages/google/cloud/secretmanager_v1/types/resources.py", line 40, in <module>
    class Secret(proto.Message):
  File "/usr/local/lib/python3.7/site-packages/proto/message.py", line 230, in __new__
    options=opts,
  File "/usr/local/lib/python3.7/site-packages/airflow/utils/timeout.py", line 69, in handle_timeout
    raise AirflowTaskTimeout(self.error_message)
airflow.exceptions.AirflowTaskTimeout: DagBag import timeout for /opt/airflow/dags/upload_task.py after 30.0s.
Please take a look at these docs to improve your DAG import time:
* https://airflow.apache.org/docs/apache-airflow/2.4.0/best-practices.html#top-level-python-code
* https://airflow.apache.org/docs/apache-airflow/2.4.0/best-practices.html#reducing-dag-complexity, PID: 592
[2023-10-26T07:07:35.510+0000] {processor.py:770} WARNING - No viable dags retrieved from /opt/airflow/dags/upload_task.py
[2023-10-26T07:07:46.068+0000] {processor.py:181} ERROR - Got an exception! Propagating...
Traceback (most recent call last):
  File "/usr/local/lib/python3.7/site-packages/sqlalchemy/engine/base.py", line 3371, in _wrap_pool_connect
    return fn()
  File "/usr/local/lib/python3.7/site-packages/sqlalchemy/pool/base.py", line 327, in connect
    return _ConnectionFairy._checkout(self)
  File "/usr/local/lib/python3.7/site-packages/sqlalchemy/pool/base.py", line 894, in _checkout
    fairy = _ConnectionRecord.checkout(pool)
  File "/usr/local/lib/python3.7/site-packages/sqlalchemy/pool/base.py", line 493, in checkout
    rec = pool._do_get()
  File "/usr/local/lib/python3.7/site-packages/sqlalchemy/pool/impl.py", line 146, in _do_get
    self._dec_overflow()
  File "/usr/local/lib/python3.7/site-packages/sqlalchemy/util/langhelpers.py", line 72, in __exit__
    with_traceback=exc_tb,
  File "/usr/local/lib/python3.7/site-packages/sqlalchemy/util/compat.py", line 211, in raise_
    raise exception
  File "/usr/local/lib/python3.7/site-packages/sqlalchemy/pool/impl.py", line 143, in _do_get
    return self._create_connection()
  File "/usr/local/lib/python3.7/site-packages/sqlalchemy/pool/base.py", line 273, in _create_connection
    return _ConnectionRecord(self)
  File "/usr/local/lib/python3.7/site-packages/sqlalchemy/pool/base.py", line 388, in __init__
    self.__connect()
  File "/usr/local/lib/python3.7/site-packages/sqlalchemy/pool/base.py", line 691, in __connect
    pool.logger.debug("Error on connect(): %s", e)
  File "/usr/local/lib/python3.7/site-packages/sqlalchemy/util/langhelpers.py", line 72, in __exit__
    with_traceback=exc_tb,
  File "/usr/local/lib/python3.7/site-packages/sqlalchemy/util/compat.py", line 211, in raise_
    raise exception
  File "/usr/local/lib/python3.7/site-packages/sqlalchemy/pool/base.py", line 686, in __connect
    self.dbapi_connection = connection = pool._invoke_creator(self)
  File "/usr/local/lib/python3.7/site-packages/sqlalchemy/engine/create.py", line 574, in connect
    return dialect.connect(*cargs, **cparams)
  File "/usr/local/lib/python3.7/site-packages/sqlalchemy/engine/default.py", line 598, in connect
    return self.dbapi.connect(*cargs, **cparams)
  File "/usr/local/lib/python3.7/site-packages/psycopg2/__init__.py", line 122, in connect
    conn = _connect(dsn, connection_factory=connection_factory, **kwasync)
psycopg2.OperationalError: could not translate host name "postgres" to address: Temporary failure in name resolution


The above exception was the direct cause of the following exception:

Traceback (most recent call last):
  File "/usr/local/lib/python3.7/site-packages/airflow/dag_processing/processor.py", line 177, in _run_file_processor
    _handle_dag_file_processing()
  File "/usr/local/lib/python3.7/site-packages/airflow/dag_processing/processor.py", line 161, in _handle_dag_file_processing
    callback_requests=callback_requests,
  File "/usr/local/lib/python3.7/site-packages/airflow/utils/session.py", line 75, in wrapper
    return func(*args, session=session, **kwargs)
  File "/usr/local/lib/python3.7/site-packages/airflow/dag_processing/processor.py", line 771, in process_file
    self.update_import_errors(session, dagbag)
  File "/usr/local/lib/python3.7/site-packages/airflow/dag_processing/processor.py", line 558, in update_import_errors
    existing_import_error_files = [x.filename for x in session.query(errors.ImportError.filename).all()]
  File "/usr/local/lib/python3.7/site-packages/sqlalchemy/orm/query.py", line 2773, in all
    return self._iter().all()
  File "/usr/local/lib/python3.7/site-packages/sqlalchemy/orm/query.py", line 2919, in _iter
    execution_options={"_sa_orm_load_options": self.load_options},
  File "/usr/local/lib/python3.7/site-packages/sqlalchemy/orm/session.py", line 1716, in execute
    conn = self._connection_for_bind(bind)
  File "/usr/local/lib/python3.7/site-packages/sqlalchemy/orm/session.py", line 1556, in _connection_for_bind
    engine, execution_options
  File "/usr/local/lib/python3.7/site-packages/sqlalchemy/orm/session.py", line 750, in _connection_for_bind
    conn = bind.connect()
  File "/usr/local/lib/python3.7/site-packages/sqlalchemy/engine/base.py", line 3325, in connect
    return self._connection_cls(self, close_with_result=close_with_result)
  File "/usr/local/lib/python3.7/site-packages/sqlalchemy/engine/base.py", line 96, in __init__
    else engine.raw_connection()
  File "/usr/local/lib/python3.7/site-packages/sqlalchemy/engine/base.py", line 3404, in raw_connection
    return self._wrap_pool_connect(self.pool.connect, _connection)
  File "/usr/local/lib/python3.7/site-packages/sqlalchemy/engine/base.py", line 3375, in _wrap_pool_connect
    e, dialect, self
  File "/usr/local/lib/python3.7/site-packages/sqlalchemy/engine/base.py", line 2209, in _handle_dbapi_exception_noconnection
    sqlalchemy_exception, with_traceback=exc_info[2], from_=e
  File "/usr/local/lib/python3.7/site-packages/sqlalchemy/util/compat.py", line 211, in raise_
    raise exception
  File "/usr/local/lib/python3.7/site-packages/sqlalchemy/engine/base.py", line 3371, in _wrap_pool_connect
    return fn()
  File "/usr/local/lib/python3.7/site-packages/sqlalchemy/pool/base.py", line 327, in connect
    return _ConnectionFairy._checkout(self)
  File "/usr/local/lib/python3.7/site-packages/sqlalchemy/pool/base.py", line 894, in _checkout
    fairy = _ConnectionRecord.checkout(pool)
  File "/usr/local/lib/python3.7/site-packages/sqlalchemy/pool/base.py", line 493, in checkout
    rec = pool._do_get()
  File "/usr/local/lib/python3.7/site-packages/sqlalchemy/pool/impl.py", line 146, in _do_get
    self._dec_overflow()
  File "/usr/local/lib/python3.7/site-packages/sqlalchemy/util/langhelpers.py", line 72, in __exit__
    with_traceback=exc_tb,
  File "/usr/local/lib/python3.7/site-packages/sqlalchemy/util/compat.py", line 211, in raise_
    raise exception
  File "/usr/local/lib/python3.7/site-packages/sqlalchemy/pool/impl.py", line 143, in _do_get
    return self._create_connection()
  File "/usr/local/lib/python3.7/site-packages/sqlalchemy/pool/base.py", line 273, in _create_connection
    return _ConnectionRecord(self)
  File "/usr/local/lib/python3.7/site-packages/sqlalchemy/pool/base.py", line 388, in __init__
    self.__connect()
  File "/usr/local/lib/python3.7/site-packages/sqlalchemy/pool/base.py", line 691, in __connect
    pool.logger.debug("Error on connect(): %s", e)
  File "/usr/local/lib/python3.7/site-packages/sqlalchemy/util/langhelpers.py", line 72, in __exit__
    with_traceback=exc_tb,
  File "/usr/local/lib/python3.7/site-packages/sqlalchemy/util/compat.py", line 211, in raise_
    raise exception
  File "/usr/local/lib/python3.7/site-packages/sqlalchemy/pool/base.py", line 686, in __connect
    self.dbapi_connection = connection = pool._invoke_creator(self)
  File "/usr/local/lib/python3.7/site-packages/sqlalchemy/engine/create.py", line 574, in connect
    return dialect.connect(*cargs, **cparams)
  File "/usr/local/lib/python3.7/site-packages/sqlalchemy/engine/default.py", line 598, in connect
    return self.dbapi.connect(*cargs, **cparams)
  File "/usr/local/lib/python3.7/site-packages/psycopg2/__init__.py", line 122, in connect
    conn = _connect(dsn, connection_factory=connection_factory, **kwasync)
sqlalchemy.exc.OperationalError: (psycopg2.OperationalError) could not translate host name "postgres" to address: Temporary failure in name resolution

(Background on this error at: https://sqlalche.me/e/14/e3q8)
[2023-10-26T07:09:52.382+0000] {processor.py:156} INFO - Started process (PID=27) to work on /opt/airflow/dags/upload_task.py
[2023-10-26T07:09:52.388+0000] {processor.py:758} INFO - Processing file /opt/airflow/dags/upload_task.py for tasks to queue
[2023-10-26T07:09:52.392+0000] {logging_mixin.py:117} INFO - [2023-10-26T07:09:52.391+0000] {dagbag.py:525} INFO - Filling up the DagBag from /opt/airflow/dags/upload_task.py
[2023-10-26T07:09:57.041+0000] {logging_mixin.py:117} INFO - [2023-10-26T07:09:57.012+0000] {dagbag.py:330} ERROR - Failed to import: /opt/airflow/dags/upload_task.py
Traceback (most recent call last):
  File "/usr/local/lib/python3.7/site-packages/airflow/models/dagbag.py", line 326, in parse
    loader.exec_module(new_module)
  File "<frozen importlib._bootstrap_external>", line 728, in exec_module
  File "<frozen importlib._bootstrap>", line 219, in _call_with_frames_removed
  File "/opt/airflow/dags/upload_task.py", line 19, in <module>
    gcp_conn_id = ""
  File "/usr/local/lib/python3.7/site-packages/airflow/models/baseoperator.py", line 394, in apply_defaults
    raise AirflowException(f"missing keyword arguments {display}")
airflow.exceptions.AirflowException: missing keyword arguments 'drive_folder', 'local_paths'
[2023-10-26T07:09:57.055+0000] {processor.py:770} WARNING - No viable dags retrieved from /opt/airflow/dags/upload_task.py
[2023-10-26T07:09:57.176+0000] {processor.py:178} INFO - Processing /opt/airflow/dags/upload_task.py took 4.841 seconds
[2023-10-26T07:13:41.656+0000] {processor.py:156} INFO - Started process (PID=26) to work on /opt/airflow/dags/upload_task.py
[2023-10-26T07:13:41.682+0000] {processor.py:758} INFO - Processing file /opt/airflow/dags/upload_task.py for tasks to queue
[2023-10-26T07:13:41.694+0000] {logging_mixin.py:117} INFO - [2023-10-26T07:13:41.693+0000] {dagbag.py:525} INFO - Filling up the DagBag from /opt/airflow/dags/upload_task.py
[2023-10-26T07:13:44.465+0000] {logging_mixin.py:117} INFO - [2023-10-26T07:13:44.417+0000] {dagbag.py:330} ERROR - Failed to import: /opt/airflow/dags/upload_task.py
Traceback (most recent call last):
  File "/usr/local/lib/python3.7/site-packages/airflow/models/dagbag.py", line 326, in parse
    loader.exec_module(new_module)
  File "<frozen importlib._bootstrap_external>", line 728, in exec_module
  File "<frozen importlib._bootstrap>", line 219, in _call_with_frames_removed
  File "/opt/airflow/dags/upload_task.py", line 19, in <module>
    gcp_conn_id = ""
  File "/usr/local/lib/python3.7/site-packages/airflow/models/baseoperator.py", line 394, in apply_defaults
    raise AirflowException(f"missing keyword arguments {display}")
airflow.exceptions.AirflowException: missing keyword arguments 'drive_folder', 'local_paths'
[2023-10-26T07:13:44.479+0000] {processor.py:770} WARNING - No viable dags retrieved from /opt/airflow/dags/upload_task.py
[2023-10-26T07:13:44.551+0000] {processor.py:178} INFO - Processing /opt/airflow/dags/upload_task.py took 2.978 seconds
[2023-10-26T07:14:14.938+0000] {processor.py:156} INFO - Started process (PID=151) to work on /opt/airflow/dags/upload_task.py
[2023-10-26T07:14:14.945+0000] {processor.py:758} INFO - Processing file /opt/airflow/dags/upload_task.py for tasks to queue
[2023-10-26T07:14:14.964+0000] {logging_mixin.py:117} INFO - [2023-10-26T07:14:14.962+0000] {dagbag.py:525} INFO - Filling up the DagBag from /opt/airflow/dags/upload_task.py
[2023-10-26T07:14:21.261+0000] {logging_mixin.py:117} INFO - [2023-10-26T07:14:21.249+0000] {dagbag.py:330} ERROR - Failed to import: /opt/airflow/dags/upload_task.py
Traceback (most recent call last):
  File "/usr/local/lib/python3.7/site-packages/airflow/models/dagbag.py", line 326, in parse
    loader.exec_module(new_module)
  File "<frozen importlib._bootstrap_external>", line 728, in exec_module
  File "<frozen importlib._bootstrap>", line 219, in _call_with_frames_removed
  File "/opt/airflow/dags/upload_task.py", line 19, in <module>
    gcp_conn_id = ""
  File "/usr/local/lib/python3.7/site-packages/airflow/models/baseoperator.py", line 394, in apply_defaults
    raise AirflowException(f"missing keyword arguments {display}")
airflow.exceptions.AirflowException: missing keyword arguments 'drive_folder', 'local_paths'
[2023-10-26T07:14:21.268+0000] {processor.py:770} WARNING - No viable dags retrieved from /opt/airflow/dags/upload_task.py
[2023-10-26T07:14:31.286+0000] {processor.py:181} ERROR - Got an exception! Propagating...
Traceback (most recent call last):
  File "/usr/local/lib/python3.7/site-packages/sqlalchemy/engine/base.py", line 3371, in _wrap_pool_connect
    return fn()
  File "/usr/local/lib/python3.7/site-packages/sqlalchemy/pool/base.py", line 327, in connect
    return _ConnectionFairy._checkout(self)
  File "/usr/local/lib/python3.7/site-packages/sqlalchemy/pool/base.py", line 894, in _checkout
    fairy = _ConnectionRecord.checkout(pool)
  File "/usr/local/lib/python3.7/site-packages/sqlalchemy/pool/base.py", line 493, in checkout
    rec = pool._do_get()
  File "/usr/local/lib/python3.7/site-packages/sqlalchemy/pool/impl.py", line 146, in _do_get
    self._dec_overflow()
  File "/usr/local/lib/python3.7/site-packages/sqlalchemy/util/langhelpers.py", line 72, in __exit__
    with_traceback=exc_tb,
  File "/usr/local/lib/python3.7/site-packages/sqlalchemy/util/compat.py", line 211, in raise_
    raise exception
  File "/usr/local/lib/python3.7/site-packages/sqlalchemy/pool/impl.py", line 143, in _do_get
    return self._create_connection()
  File "/usr/local/lib/python3.7/site-packages/sqlalchemy/pool/base.py", line 273, in _create_connection
    return _ConnectionRecord(self)
  File "/usr/local/lib/python3.7/site-packages/sqlalchemy/pool/base.py", line 388, in __init__
    self.__connect()
  File "/usr/local/lib/python3.7/site-packages/sqlalchemy/pool/base.py", line 691, in __connect
    pool.logger.debug("Error on connect(): %s", e)
  File "/usr/local/lib/python3.7/site-packages/sqlalchemy/util/langhelpers.py", line 72, in __exit__
    with_traceback=exc_tb,
  File "/usr/local/lib/python3.7/site-packages/sqlalchemy/util/compat.py", line 211, in raise_
    raise exception
  File "/usr/local/lib/python3.7/site-packages/sqlalchemy/pool/base.py", line 686, in __connect
    self.dbapi_connection = connection = pool._invoke_creator(self)
  File "/usr/local/lib/python3.7/site-packages/sqlalchemy/engine/create.py", line 574, in connect
    return dialect.connect(*cargs, **cparams)
  File "/usr/local/lib/python3.7/site-packages/sqlalchemy/engine/default.py", line 598, in connect
    return self.dbapi.connect(*cargs, **cparams)
  File "/usr/local/lib/python3.7/site-packages/psycopg2/__init__.py", line 122, in connect
    conn = _connect(dsn, connection_factory=connection_factory, **kwasync)
psycopg2.OperationalError: could not translate host name "postgres" to address: Temporary failure in name resolution


The above exception was the direct cause of the following exception:

Traceback (most recent call last):
  File "/usr/local/lib/python3.7/site-packages/airflow/dag_processing/processor.py", line 177, in _run_file_processor
    _handle_dag_file_processing()
  File "/usr/local/lib/python3.7/site-packages/airflow/dag_processing/processor.py", line 161, in _handle_dag_file_processing
    callback_requests=callback_requests,
  File "/usr/local/lib/python3.7/site-packages/airflow/utils/session.py", line 75, in wrapper
    return func(*args, session=session, **kwargs)
  File "/usr/local/lib/python3.7/site-packages/airflow/dag_processing/processor.py", line 771, in process_file
    self.update_import_errors(session, dagbag)
  File "/usr/local/lib/python3.7/site-packages/airflow/dag_processing/processor.py", line 558, in update_import_errors
    existing_import_error_files = [x.filename for x in session.query(errors.ImportError.filename).all()]
  File "/usr/local/lib/python3.7/site-packages/sqlalchemy/orm/query.py", line 2773, in all
    return self._iter().all()
  File "/usr/local/lib/python3.7/site-packages/sqlalchemy/orm/query.py", line 2919, in _iter
    execution_options={"_sa_orm_load_options": self.load_options},
  File "/usr/local/lib/python3.7/site-packages/sqlalchemy/orm/session.py", line 1716, in execute
    conn = self._connection_for_bind(bind)
  File "/usr/local/lib/python3.7/site-packages/sqlalchemy/orm/session.py", line 1556, in _connection_for_bind
    engine, execution_options
  File "/usr/local/lib/python3.7/site-packages/sqlalchemy/orm/session.py", line 750, in _connection_for_bind
    conn = bind.connect()
  File "/usr/local/lib/python3.7/site-packages/sqlalchemy/engine/base.py", line 3325, in connect
    return self._connection_cls(self, close_with_result=close_with_result)
  File "/usr/local/lib/python3.7/site-packages/sqlalchemy/engine/base.py", line 96, in __init__
    else engine.raw_connection()
  File "/usr/local/lib/python3.7/site-packages/sqlalchemy/engine/base.py", line 3404, in raw_connection
    return self._wrap_pool_connect(self.pool.connect, _connection)
  File "/usr/local/lib/python3.7/site-packages/sqlalchemy/engine/base.py", line 3375, in _wrap_pool_connect
    e, dialect, self
  File "/usr/local/lib/python3.7/site-packages/sqlalchemy/engine/base.py", line 2209, in _handle_dbapi_exception_noconnection
    sqlalchemy_exception, with_traceback=exc_info[2], from_=e
  File "/usr/local/lib/python3.7/site-packages/sqlalchemy/util/compat.py", line 211, in raise_
    raise exception
  File "/usr/local/lib/python3.7/site-packages/sqlalchemy/engine/base.py", line 3371, in _wrap_pool_connect
    return fn()
  File "/usr/local/lib/python3.7/site-packages/sqlalchemy/pool/base.py", line 327, in connect
    return _ConnectionFairy._checkout(self)
  File "/usr/local/lib/python3.7/site-packages/sqlalchemy/pool/base.py", line 894, in _checkout
    fairy = _ConnectionRecord.checkout(pool)
  File "/usr/local/lib/python3.7/site-packages/sqlalchemy/pool/base.py", line 493, in checkout
    rec = pool._do_get()
  File "/usr/local/lib/python3.7/site-packages/sqlalchemy/pool/impl.py", line 146, in _do_get
    self._dec_overflow()
  File "/usr/local/lib/python3.7/site-packages/sqlalchemy/util/langhelpers.py", line 72, in __exit__
    with_traceback=exc_tb,
  File "/usr/local/lib/python3.7/site-packages/sqlalchemy/util/compat.py", line 211, in raise_
    raise exception
  File "/usr/local/lib/python3.7/site-packages/sqlalchemy/pool/impl.py", line 143, in _do_get
    return self._create_connection()
  File "/usr/local/lib/python3.7/site-packages/sqlalchemy/pool/base.py", line 273, in _create_connection
    return _ConnectionRecord(self)
  File "/usr/local/lib/python3.7/site-packages/sqlalchemy/pool/base.py", line 388, in __init__
    self.__connect()
  File "/usr/local/lib/python3.7/site-packages/sqlalchemy/pool/base.py", line 691, in __connect
    pool.logger.debug("Error on connect(): %s", e)
  File "/usr/local/lib/python3.7/site-packages/sqlalchemy/util/langhelpers.py", line 72, in __exit__
    with_traceback=exc_tb,
  File "/usr/local/lib/python3.7/site-packages/sqlalchemy/util/compat.py", line 211, in raise_
    raise exception
  File "/usr/local/lib/python3.7/site-packages/sqlalchemy/pool/base.py", line 686, in __connect
    self.dbapi_connection = connection = pool._invoke_creator(self)
  File "/usr/local/lib/python3.7/site-packages/sqlalchemy/engine/create.py", line 574, in connect
    return dialect.connect(*cargs, **cparams)
  File "/usr/local/lib/python3.7/site-packages/sqlalchemy/engine/default.py", line 598, in connect
    return self.dbapi.connect(*cargs, **cparams)
  File "/usr/local/lib/python3.7/site-packages/psycopg2/__init__.py", line 122, in connect
    conn = _connect(dsn, connection_factory=connection_factory, **kwasync)
sqlalchemy.exc.OperationalError: (psycopg2.OperationalError) could not translate host name "postgres" to address: Temporary failure in name resolution

(Background on this error at: https://sqlalche.me/e/14/e3q8)
[2023-10-26T07:15:16.433+0000] {processor.py:156} INFO - Started process (PID=240) to work on /opt/airflow/dags/upload_task.py
[2023-10-26T07:15:16.440+0000] {processor.py:758} INFO - Processing file /opt/airflow/dags/upload_task.py for tasks to queue
[2023-10-26T07:15:16.450+0000] {logging_mixin.py:117} INFO - [2023-10-26T07:15:16.449+0000] {dagbag.py:525} INFO - Filling up the DagBag from /opt/airflow/dags/upload_task.py
[2023-10-26T07:15:22.003+0000] {logging_mixin.py:117} INFO - [2023-10-26T07:15:21.983+0000] {dagbag.py:330} ERROR - Failed to import: /opt/airflow/dags/upload_task.py
Traceback (most recent call last):
  File "/usr/local/lib/python3.7/site-packages/airflow/models/dagbag.py", line 326, in parse
    loader.exec_module(new_module)
  File "<frozen importlib._bootstrap_external>", line 728, in exec_module
  File "<frozen importlib._bootstrap>", line 219, in _call_with_frames_removed
  File "/opt/airflow/dags/upload_task.py", line 19, in <module>
    gcp_conn_id = ""
  File "/usr/local/lib/python3.7/site-packages/airflow/models/baseoperator.py", line 394, in apply_defaults
    raise AirflowException(f"missing keyword arguments {display}")
airflow.exceptions.AirflowException: missing keyword arguments 'drive_folder', 'local_paths'
[2023-10-26T07:15:22.015+0000] {processor.py:770} WARNING - No viable dags retrieved from /opt/airflow/dags/upload_task.py
[2023-10-26T07:15:34.010+0000] {processor.py:181} ERROR - Got an exception! Propagating...
Traceback (most recent call last):
  File "/usr/local/lib/python3.7/site-packages/sqlalchemy/engine/base.py", line 3371, in _wrap_pool_connect
    return fn()
  File "/usr/local/lib/python3.7/site-packages/sqlalchemy/pool/base.py", line 327, in connect
    return _ConnectionFairy._checkout(self)
  File "/usr/local/lib/python3.7/site-packages/sqlalchemy/pool/base.py", line 894, in _checkout
    fairy = _ConnectionRecord.checkout(pool)
  File "/usr/local/lib/python3.7/site-packages/sqlalchemy/pool/base.py", line 493, in checkout
    rec = pool._do_get()
  File "/usr/local/lib/python3.7/site-packages/sqlalchemy/pool/impl.py", line 146, in _do_get
    self._dec_overflow()
  File "/usr/local/lib/python3.7/site-packages/sqlalchemy/util/langhelpers.py", line 72, in __exit__
    with_traceback=exc_tb,
  File "/usr/local/lib/python3.7/site-packages/sqlalchemy/util/compat.py", line 211, in raise_
    raise exception
  File "/usr/local/lib/python3.7/site-packages/sqlalchemy/pool/impl.py", line 143, in _do_get
    return self._create_connection()
  File "/usr/local/lib/python3.7/site-packages/sqlalchemy/pool/base.py", line 273, in _create_connection
    return _ConnectionRecord(self)
  File "/usr/local/lib/python3.7/site-packages/sqlalchemy/pool/base.py", line 388, in __init__
    self.__connect()
  File "/usr/local/lib/python3.7/site-packages/sqlalchemy/pool/base.py", line 691, in __connect
    pool.logger.debug("Error on connect(): %s", e)
  File "/usr/local/lib/python3.7/site-packages/sqlalchemy/util/langhelpers.py", line 72, in __exit__
    with_traceback=exc_tb,
  File "/usr/local/lib/python3.7/site-packages/sqlalchemy/util/compat.py", line 211, in raise_
    raise exception
  File "/usr/local/lib/python3.7/site-packages/sqlalchemy/pool/base.py", line 686, in __connect
    self.dbapi_connection = connection = pool._invoke_creator(self)
  File "/usr/local/lib/python3.7/site-packages/sqlalchemy/engine/create.py", line 574, in connect
    return dialect.connect(*cargs, **cparams)
  File "/usr/local/lib/python3.7/site-packages/sqlalchemy/engine/default.py", line 598, in connect
    return self.dbapi.connect(*cargs, **cparams)
  File "/usr/local/lib/python3.7/site-packages/psycopg2/__init__.py", line 122, in connect
    conn = _connect(dsn, connection_factory=connection_factory, **kwasync)
psycopg2.OperationalError: could not translate host name "postgres" to address: Temporary failure in name resolution


The above exception was the direct cause of the following exception:

Traceback (most recent call last):
  File "/usr/local/lib/python3.7/site-packages/airflow/dag_processing/processor.py", line 177, in _run_file_processor
    _handle_dag_file_processing()
  File "/usr/local/lib/python3.7/site-packages/airflow/dag_processing/processor.py", line 161, in _handle_dag_file_processing
    callback_requests=callback_requests,
  File "/usr/local/lib/python3.7/site-packages/airflow/utils/session.py", line 75, in wrapper
    return func(*args, session=session, **kwargs)
  File "/usr/local/lib/python3.7/site-packages/airflow/dag_processing/processor.py", line 771, in process_file
    self.update_import_errors(session, dagbag)
  File "/usr/local/lib/python3.7/site-packages/airflow/dag_processing/processor.py", line 558, in update_import_errors
    existing_import_error_files = [x.filename for x in session.query(errors.ImportError.filename).all()]
  File "/usr/local/lib/python3.7/site-packages/sqlalchemy/orm/query.py", line 2773, in all
    return self._iter().all()
  File "/usr/local/lib/python3.7/site-packages/sqlalchemy/orm/query.py", line 2919, in _iter
    execution_options={"_sa_orm_load_options": self.load_options},
  File "/usr/local/lib/python3.7/site-packages/sqlalchemy/orm/session.py", line 1716, in execute
    conn = self._connection_for_bind(bind)
  File "/usr/local/lib/python3.7/site-packages/sqlalchemy/orm/session.py", line 1556, in _connection_for_bind
    engine, execution_options
  File "/usr/local/lib/python3.7/site-packages/sqlalchemy/orm/session.py", line 750, in _connection_for_bind
    conn = bind.connect()
  File "/usr/local/lib/python3.7/site-packages/sqlalchemy/engine/base.py", line 3325, in connect
    return self._connection_cls(self, close_with_result=close_with_result)
  File "/usr/local/lib/python3.7/site-packages/sqlalchemy/engine/base.py", line 96, in __init__
    else engine.raw_connection()
  File "/usr/local/lib/python3.7/site-packages/sqlalchemy/engine/base.py", line 3404, in raw_connection
    return self._wrap_pool_connect(self.pool.connect, _connection)
  File "/usr/local/lib/python3.7/site-packages/sqlalchemy/engine/base.py", line 3375, in _wrap_pool_connect
    e, dialect, self
  File "/usr/local/lib/python3.7/site-packages/sqlalchemy/engine/base.py", line 2209, in _handle_dbapi_exception_noconnection
    sqlalchemy_exception, with_traceback=exc_info[2], from_=e
  File "/usr/local/lib/python3.7/site-packages/sqlalchemy/util/compat.py", line 211, in raise_
    raise exception
  File "/usr/local/lib/python3.7/site-packages/sqlalchemy/engine/base.py", line 3371, in _wrap_pool_connect
    return fn()
  File "/usr/local/lib/python3.7/site-packages/sqlalchemy/pool/base.py", line 327, in connect
    return _ConnectionFairy._checkout(self)
  File "/usr/local/lib/python3.7/site-packages/sqlalchemy/pool/base.py", line 894, in _checkout
    fairy = _ConnectionRecord.checkout(pool)
  File "/usr/local/lib/python3.7/site-packages/sqlalchemy/pool/base.py", line 493, in checkout
    rec = pool._do_get()
  File "/usr/local/lib/python3.7/site-packages/sqlalchemy/pool/impl.py", line 146, in _do_get
    self._dec_overflow()
  File "/usr/local/lib/python3.7/site-packages/sqlalchemy/util/langhelpers.py", line 72, in __exit__
    with_traceback=exc_tb,
  File "/usr/local/lib/python3.7/site-packages/sqlalchemy/util/compat.py", line 211, in raise_
    raise exception
  File "/usr/local/lib/python3.7/site-packages/sqlalchemy/pool/impl.py", line 143, in _do_get
    return self._create_connection()
  File "/usr/local/lib/python3.7/site-packages/sqlalchemy/pool/base.py", line 273, in _create_connection
    return _ConnectionRecord(self)
  File "/usr/local/lib/python3.7/site-packages/sqlalchemy/pool/base.py", line 388, in __init__
    self.__connect()
  File "/usr/local/lib/python3.7/site-packages/sqlalchemy/pool/base.py", line 691, in __connect
    pool.logger.debug("Error on connect(): %s", e)
  File "/usr/local/lib/python3.7/site-packages/sqlalchemy/util/langhelpers.py", line 72, in __exit__
    with_traceback=exc_tb,
  File "/usr/local/lib/python3.7/site-packages/sqlalchemy/util/compat.py", line 211, in raise_
    raise exception
  File "/usr/local/lib/python3.7/site-packages/sqlalchemy/pool/base.py", line 686, in __connect
    self.dbapi_connection = connection = pool._invoke_creator(self)
  File "/usr/local/lib/python3.7/site-packages/sqlalchemy/engine/create.py", line 574, in connect
    return dialect.connect(*cargs, **cparams)
  File "/usr/local/lib/python3.7/site-packages/sqlalchemy/engine/default.py", line 598, in connect
    return self.dbapi.connect(*cargs, **cparams)
  File "/usr/local/lib/python3.7/site-packages/psycopg2/__init__.py", line 122, in connect
    conn = _connect(dsn, connection_factory=connection_factory, **kwasync)
sqlalchemy.exc.OperationalError: (psycopg2.OperationalError) could not translate host name "postgres" to address: Temporary failure in name resolution

(Background on this error at: https://sqlalche.me/e/14/e3q8)
[2023-10-26T07:16:09.412+0000] {processor.py:156} INFO - Started process (PID=335) to work on /opt/airflow/dags/upload_task.py
[2023-10-26T07:16:09.416+0000] {processor.py:758} INFO - Processing file /opt/airflow/dags/upload_task.py for tasks to queue
[2023-10-26T07:16:09.420+0000] {logging_mixin.py:117} INFO - [2023-10-26T07:16:09.418+0000] {dagbag.py:525} INFO - Filling up the DagBag from /opt/airflow/dags/upload_task.py
[2023-10-26T07:16:41.049+0000] {logging_mixin.py:117} INFO - [2023-10-26T07:16:41.035+0000] {timeout.py:68} ERROR - Process timed out, PID: 335
[2023-10-26T07:16:41.115+0000] {logging_mixin.py:117} INFO - [2023-10-26T07:16:41.051+0000] {dagbag.py:330} ERROR - Failed to import: /opt/airflow/dags/upload_task.py
Traceback (most recent call last):
  File "/usr/local/lib/python3.7/site-packages/airflow/models/dagbag.py", line 326, in parse
    loader.exec_module(new_module)
  File "<frozen importlib._bootstrap_external>", line 728, in exec_module
  File "<frozen importlib._bootstrap>", line 219, in _call_with_frames_removed
  File "/opt/airflow/dags/upload_task.py", line 1, in <module>
    from airflow.providers.google.suite.transfers.local_to_drive import LocalFilesystemToGoogleDriveOperator
  File "/usr/local/lib/python3.7/site-packages/airflow/providers/google/suite/transfers/local_to_drive.py", line 26, in <module>
    from airflow.providers.google.suite.hooks.drive import GoogleDriveHook
  File "/usr/local/lib/python3.7/site-packages/airflow/providers/google/suite/hooks/drive.py", line 27, in <module>
    from airflow.providers.google.common.hooks.base_google import GoogleBaseHook
  File "/usr/local/lib/python3.7/site-packages/airflow/providers/google/common/hooks/base_google.py", line 39, in <module>
    from google.api_core.gapic_v1.client_info import ClientInfo
  File "/usr/local/lib/python3.7/site-packages/google/api_core/gapic_v1/__init__.py", line 17, in <module>
    from google.api_core.gapic_v1 import config_async
  File "/usr/local/lib/python3.7/site-packages/google/api_core/gapic_v1/config_async.py", line 18, in <module>
    """
  File "/usr/local/lib/python3.7/site-packages/airflow/utils/timeout.py", line 69, in handle_timeout
    raise AirflowTaskTimeout(self.error_message)
airflow.exceptions.AirflowTaskTimeout: DagBag import timeout for /opt/airflow/dags/upload_task.py after 30.0s.
Please take a look at these docs to improve your DAG import time:
* https://airflow.apache.org/docs/apache-airflow/2.4.0/best-practices.html#top-level-python-code
* https://airflow.apache.org/docs/apache-airflow/2.4.0/best-practices.html#reducing-dag-complexity, PID: 335
[2023-10-26T07:16:41.117+0000] {processor.py:770} WARNING - No viable dags retrieved from /opt/airflow/dags/upload_task.py
[2023-10-26T07:16:51.224+0000] {processor.py:181} ERROR - Got an exception! Propagating...
Traceback (most recent call last):
  File "/usr/local/lib/python3.7/site-packages/sqlalchemy/engine/base.py", line 3371, in _wrap_pool_connect
    return fn()
  File "/usr/local/lib/python3.7/site-packages/sqlalchemy/pool/base.py", line 327, in connect
    return _ConnectionFairy._checkout(self)
  File "/usr/local/lib/python3.7/site-packages/sqlalchemy/pool/base.py", line 894, in _checkout
    fairy = _ConnectionRecord.checkout(pool)
  File "/usr/local/lib/python3.7/site-packages/sqlalchemy/pool/base.py", line 493, in checkout
    rec = pool._do_get()
  File "/usr/local/lib/python3.7/site-packages/sqlalchemy/pool/impl.py", line 146, in _do_get
    self._dec_overflow()
  File "/usr/local/lib/python3.7/site-packages/sqlalchemy/util/langhelpers.py", line 72, in __exit__
    with_traceback=exc_tb,
  File "/usr/local/lib/python3.7/site-packages/sqlalchemy/util/compat.py", line 211, in raise_
    raise exception
  File "/usr/local/lib/python3.7/site-packages/sqlalchemy/pool/impl.py", line 143, in _do_get
    return self._create_connection()
  File "/usr/local/lib/python3.7/site-packages/sqlalchemy/pool/base.py", line 273, in _create_connection
    return _ConnectionRecord(self)
  File "/usr/local/lib/python3.7/site-packages/sqlalchemy/pool/base.py", line 388, in __init__
    self.__connect()
  File "/usr/local/lib/python3.7/site-packages/sqlalchemy/pool/base.py", line 691, in __connect
    pool.logger.debug("Error on connect(): %s", e)
  File "/usr/local/lib/python3.7/site-packages/sqlalchemy/util/langhelpers.py", line 72, in __exit__
    with_traceback=exc_tb,
  File "/usr/local/lib/python3.7/site-packages/sqlalchemy/util/compat.py", line 211, in raise_
    raise exception
  File "/usr/local/lib/python3.7/site-packages/sqlalchemy/pool/base.py", line 686, in __connect
    self.dbapi_connection = connection = pool._invoke_creator(self)
  File "/usr/local/lib/python3.7/site-packages/sqlalchemy/engine/create.py", line 574, in connect
    return dialect.connect(*cargs, **cparams)
  File "/usr/local/lib/python3.7/site-packages/sqlalchemy/engine/default.py", line 598, in connect
    return self.dbapi.connect(*cargs, **cparams)
  File "/usr/local/lib/python3.7/site-packages/psycopg2/__init__.py", line 122, in connect
    conn = _connect(dsn, connection_factory=connection_factory, **kwasync)
psycopg2.OperationalError: could not translate host name "postgres" to address: Temporary failure in name resolution


The above exception was the direct cause of the following exception:

Traceback (most recent call last):
  File "/usr/local/lib/python3.7/site-packages/airflow/dag_processing/processor.py", line 177, in _run_file_processor
    _handle_dag_file_processing()
  File "/usr/local/lib/python3.7/site-packages/airflow/dag_processing/processor.py", line 161, in _handle_dag_file_processing
    callback_requests=callback_requests,
  File "/usr/local/lib/python3.7/site-packages/airflow/utils/session.py", line 75, in wrapper
    return func(*args, session=session, **kwargs)
  File "/usr/local/lib/python3.7/site-packages/airflow/dag_processing/processor.py", line 771, in process_file
    self.update_import_errors(session, dagbag)
  File "/usr/local/lib/python3.7/site-packages/airflow/dag_processing/processor.py", line 558, in update_import_errors
    existing_import_error_files = [x.filename for x in session.query(errors.ImportError.filename).all()]
  File "/usr/local/lib/python3.7/site-packages/sqlalchemy/orm/query.py", line 2773, in all
    return self._iter().all()
  File "/usr/local/lib/python3.7/site-packages/sqlalchemy/orm/query.py", line 2919, in _iter
    execution_options={"_sa_orm_load_options": self.load_options},
  File "/usr/local/lib/python3.7/site-packages/sqlalchemy/orm/session.py", line 1716, in execute
    conn = self._connection_for_bind(bind)
  File "/usr/local/lib/python3.7/site-packages/sqlalchemy/orm/session.py", line 1556, in _connection_for_bind
    engine, execution_options
  File "/usr/local/lib/python3.7/site-packages/sqlalchemy/orm/session.py", line 750, in _connection_for_bind
    conn = bind.connect()
  File "/usr/local/lib/python3.7/site-packages/sqlalchemy/engine/base.py", line 3325, in connect
    return self._connection_cls(self, close_with_result=close_with_result)
  File "/usr/local/lib/python3.7/site-packages/sqlalchemy/engine/base.py", line 96, in __init__
    else engine.raw_connection()
  File "/usr/local/lib/python3.7/site-packages/sqlalchemy/engine/base.py", line 3404, in raw_connection
    return self._wrap_pool_connect(self.pool.connect, _connection)
  File "/usr/local/lib/python3.7/site-packages/sqlalchemy/engine/base.py", line 3375, in _wrap_pool_connect
    e, dialect, self
  File "/usr/local/lib/python3.7/site-packages/sqlalchemy/engine/base.py", line 2209, in _handle_dbapi_exception_noconnection
    sqlalchemy_exception, with_traceback=exc_info[2], from_=e
  File "/usr/local/lib/python3.7/site-packages/sqlalchemy/util/compat.py", line 211, in raise_
    raise exception
  File "/usr/local/lib/python3.7/site-packages/sqlalchemy/engine/base.py", line 3371, in _wrap_pool_connect
    return fn()
  File "/usr/local/lib/python3.7/site-packages/sqlalchemy/pool/base.py", line 327, in connect
    return _ConnectionFairy._checkout(self)
  File "/usr/local/lib/python3.7/site-packages/sqlalchemy/pool/base.py", line 894, in _checkout
    fairy = _ConnectionRecord.checkout(pool)
  File "/usr/local/lib/python3.7/site-packages/sqlalchemy/pool/base.py", line 493, in checkout
    rec = pool._do_get()
  File "/usr/local/lib/python3.7/site-packages/sqlalchemy/pool/impl.py", line 146, in _do_get
    self._dec_overflow()
  File "/usr/local/lib/python3.7/site-packages/sqlalchemy/util/langhelpers.py", line 72, in __exit__
    with_traceback=exc_tb,
  File "/usr/local/lib/python3.7/site-packages/sqlalchemy/util/compat.py", line 211, in raise_
    raise exception
  File "/usr/local/lib/python3.7/site-packages/sqlalchemy/pool/impl.py", line 143, in _do_get
    return self._create_connection()
  File "/usr/local/lib/python3.7/site-packages/sqlalchemy/pool/base.py", line 273, in _create_connection
    return _ConnectionRecord(self)
  File "/usr/local/lib/python3.7/site-packages/sqlalchemy/pool/base.py", line 388, in __init__
    self.__connect()
  File "/usr/local/lib/python3.7/site-packages/sqlalchemy/pool/base.py", line 691, in __connect
    pool.logger.debug("Error on connect(): %s", e)
  File "/usr/local/lib/python3.7/site-packages/sqlalchemy/util/langhelpers.py", line 72, in __exit__
    with_traceback=exc_tb,
  File "/usr/local/lib/python3.7/site-packages/sqlalchemy/util/compat.py", line 211, in raise_
    raise exception
  File "/usr/local/lib/python3.7/site-packages/sqlalchemy/pool/base.py", line 686, in __connect
    self.dbapi_connection = connection = pool._invoke_creator(self)
  File "/usr/local/lib/python3.7/site-packages/sqlalchemy/engine/create.py", line 574, in connect
    return dialect.connect(*cargs, **cparams)
  File "/usr/local/lib/python3.7/site-packages/sqlalchemy/engine/default.py", line 598, in connect
    return self.dbapi.connect(*cargs, **cparams)
  File "/usr/local/lib/python3.7/site-packages/psycopg2/__init__.py", line 122, in connect
    conn = _connect(dsn, connection_factory=connection_factory, **kwasync)
sqlalchemy.exc.OperationalError: (psycopg2.OperationalError) could not translate host name "postgres" to address: Temporary failure in name resolution

(Background on this error at: https://sqlalche.me/e/14/e3q8)
[2023-10-26T07:17:22.020+0000] {processor.py:156} INFO - Started process (PID=444) to work on /opt/airflow/dags/upload_task.py
[2023-10-26T07:17:22.040+0000] {processor.py:758} INFO - Processing file /opt/airflow/dags/upload_task.py for tasks to queue
[2023-10-26T07:17:22.042+0000] {logging_mixin.py:117} INFO - [2023-10-26T07:17:22.041+0000] {dagbag.py:525} INFO - Filling up the DagBag from /opt/airflow/dags/upload_task.py
[2023-10-26T07:17:52.155+0000] {logging_mixin.py:117} INFO - [2023-10-26T07:17:52.128+0000] {timeout.py:68} ERROR - Process timed out, PID: 444
[2023-10-26T07:17:52.308+0000] {logging_mixin.py:117} INFO - [2023-10-26T07:17:52.174+0000] {dagbag.py:330} ERROR - Failed to import: /opt/airflow/dags/upload_task.py
Traceback (most recent call last):
  File "/usr/local/lib/python3.7/site-packages/airflow/models/dagbag.py", line 326, in parse
    loader.exec_module(new_module)
  File "<frozen importlib._bootstrap_external>", line 728, in exec_module
  File "<frozen importlib._bootstrap>", line 219, in _call_with_frames_removed
  File "/opt/airflow/dags/upload_task.py", line 1, in <module>
    from airflow.providers.google.suite.transfers.local_to_drive import LocalFilesystemToGoogleDriveOperator
  File "/usr/local/lib/python3.7/site-packages/airflow/providers/google/suite/transfers/local_to_drive.py", line 26, in <module>
    from airflow.providers.google.suite.hooks.drive import GoogleDriveHook
  File "/usr/local/lib/python3.7/site-packages/airflow/providers/google/suite/hooks/drive.py", line 23, in <module>
    from googleapiclient.discovery import Resource, build
  File "/usr/local/lib/python3.7/site-packages/googleapiclient/discovery.py", line 48, in <module>
    import httplib2
  File "/usr/local/lib/python3.7/site-packages/httplib2/__init__.py", line 53, in <module>
    from . import auth
  File "/usr/local/lib/python3.7/site-packages/httplib2/auth.py", line 4, in <module>
    import pyparsing as pp
  File "/usr/local/lib/python3.7/site-packages/pyparsing/__init__.py", line 141, in <module>
    from .common import (
  File "/usr/local/lib/python3.7/site-packages/pyparsing/common.py", line 8, in <module>
    class pyparsing_common:
  File "/usr/local/lib/python3.7/site-packages/pyparsing/common.py", line 219, in pyparsing_common
    identifier = Word(identchars, identbodychars).set_name("identifier")
  File "/usr/local/lib/python3.7/site-packages/pyparsing/core.py", line 2921, in __init__
    self.re = re.compile(self.reString)
  File "/usr/local/lib/python3.7/re.py", line 236, in compile
    return _compile(pattern, flags)
  File "/usr/local/lib/python3.7/re.py", line 278, in _compile
    return _cache[type(pattern), pattern, flags]
  File "/usr/local/lib/python3.7/site-packages/airflow/utils/timeout.py", line 69, in handle_timeout
    raise AirflowTaskTimeout(self.error_message)
airflow.exceptions.AirflowTaskTimeout: DagBag import timeout for /opt/airflow/dags/upload_task.py after 30.0s.
Please take a look at these docs to improve your DAG import time:
* https://airflow.apache.org/docs/apache-airflow/2.4.0/best-practices.html#top-level-python-code
* https://airflow.apache.org/docs/apache-airflow/2.4.0/best-practices.html#reducing-dag-complexity, PID: 444
[2023-10-26T07:17:52.331+0000] {processor.py:770} WARNING - No viable dags retrieved from /opt/airflow/dags/upload_task.py
[2023-10-26T07:18:02.843+0000] {processor.py:181} ERROR - Got an exception! Propagating...
Traceback (most recent call last):
  File "/usr/local/lib/python3.7/site-packages/sqlalchemy/engine/base.py", line 3371, in _wrap_pool_connect
    return fn()
  File "/usr/local/lib/python3.7/site-packages/sqlalchemy/pool/base.py", line 327, in connect
    return _ConnectionFairy._checkout(self)
  File "/usr/local/lib/python3.7/site-packages/sqlalchemy/pool/base.py", line 894, in _checkout
    fairy = _ConnectionRecord.checkout(pool)
  File "/usr/local/lib/python3.7/site-packages/sqlalchemy/pool/base.py", line 493, in checkout
    rec = pool._do_get()
  File "/usr/local/lib/python3.7/site-packages/sqlalchemy/pool/impl.py", line 146, in _do_get
    self._dec_overflow()
  File "/usr/local/lib/python3.7/site-packages/sqlalchemy/util/langhelpers.py", line 72, in __exit__
    with_traceback=exc_tb,
  File "/usr/local/lib/python3.7/site-packages/sqlalchemy/util/compat.py", line 211, in raise_
    raise exception
  File "/usr/local/lib/python3.7/site-packages/sqlalchemy/pool/impl.py", line 143, in _do_get
    return self._create_connection()
  File "/usr/local/lib/python3.7/site-packages/sqlalchemy/pool/base.py", line 273, in _create_connection
    return _ConnectionRecord(self)
  File "/usr/local/lib/python3.7/site-packages/sqlalchemy/pool/base.py", line 388, in __init__
    self.__connect()
  File "/usr/local/lib/python3.7/site-packages/sqlalchemy/pool/base.py", line 691, in __connect
    pool.logger.debug("Error on connect(): %s", e)
  File "/usr/local/lib/python3.7/site-packages/sqlalchemy/util/langhelpers.py", line 72, in __exit__
    with_traceback=exc_tb,
  File "/usr/local/lib/python3.7/site-packages/sqlalchemy/util/compat.py", line 211, in raise_
    raise exception
  File "/usr/local/lib/python3.7/site-packages/sqlalchemy/pool/base.py", line 686, in __connect
    self.dbapi_connection = connection = pool._invoke_creator(self)
  File "/usr/local/lib/python3.7/site-packages/sqlalchemy/engine/create.py", line 574, in connect
    return dialect.connect(*cargs, **cparams)
  File "/usr/local/lib/python3.7/site-packages/sqlalchemy/engine/default.py", line 598, in connect
    return self.dbapi.connect(*cargs, **cparams)
  File "/usr/local/lib/python3.7/site-packages/psycopg2/__init__.py", line 122, in connect
    conn = _connect(dsn, connection_factory=connection_factory, **kwasync)
psycopg2.OperationalError: could not translate host name "postgres" to address: Temporary failure in name resolution


The above exception was the direct cause of the following exception:

Traceback (most recent call last):
  File "/usr/local/lib/python3.7/site-packages/airflow/dag_processing/processor.py", line 177, in _run_file_processor
    _handle_dag_file_processing()
  File "/usr/local/lib/python3.7/site-packages/airflow/dag_processing/processor.py", line 161, in _handle_dag_file_processing
    callback_requests=callback_requests,
  File "/usr/local/lib/python3.7/site-packages/airflow/utils/session.py", line 75, in wrapper
    return func(*args, session=session, **kwargs)
  File "/usr/local/lib/python3.7/site-packages/airflow/dag_processing/processor.py", line 771, in process_file
    self.update_import_errors(session, dagbag)
  File "/usr/local/lib/python3.7/site-packages/airflow/dag_processing/processor.py", line 558, in update_import_errors
    existing_import_error_files = [x.filename for x in session.query(errors.ImportError.filename).all()]
  File "/usr/local/lib/python3.7/site-packages/sqlalchemy/orm/query.py", line 2773, in all
    return self._iter().all()
  File "/usr/local/lib/python3.7/site-packages/sqlalchemy/orm/query.py", line 2919, in _iter
    execution_options={"_sa_orm_load_options": self.load_options},
  File "/usr/local/lib/python3.7/site-packages/sqlalchemy/orm/session.py", line 1716, in execute
    conn = self._connection_for_bind(bind)
  File "/usr/local/lib/python3.7/site-packages/sqlalchemy/orm/session.py", line 1556, in _connection_for_bind
    engine, execution_options
  File "/usr/local/lib/python3.7/site-packages/sqlalchemy/orm/session.py", line 750, in _connection_for_bind
    conn = bind.connect()
  File "/usr/local/lib/python3.7/site-packages/sqlalchemy/engine/base.py", line 3325, in connect
    return self._connection_cls(self, close_with_result=close_with_result)
  File "/usr/local/lib/python3.7/site-packages/sqlalchemy/engine/base.py", line 96, in __init__
    else engine.raw_connection()
  File "/usr/local/lib/python3.7/site-packages/sqlalchemy/engine/base.py", line 3404, in raw_connection
    return self._wrap_pool_connect(self.pool.connect, _connection)
  File "/usr/local/lib/python3.7/site-packages/sqlalchemy/engine/base.py", line 3375, in _wrap_pool_connect
    e, dialect, self
  File "/usr/local/lib/python3.7/site-packages/sqlalchemy/engine/base.py", line 2209, in _handle_dbapi_exception_noconnection
    sqlalchemy_exception, with_traceback=exc_info[2], from_=e
  File "/usr/local/lib/python3.7/site-packages/sqlalchemy/util/compat.py", line 211, in raise_
    raise exception
  File "/usr/local/lib/python3.7/site-packages/sqlalchemy/engine/base.py", line 3371, in _wrap_pool_connect
    return fn()
  File "/usr/local/lib/python3.7/site-packages/sqlalchemy/pool/base.py", line 327, in connect
    return _ConnectionFairy._checkout(self)
  File "/usr/local/lib/python3.7/site-packages/sqlalchemy/pool/base.py", line 894, in _checkout
    fairy = _ConnectionRecord.checkout(pool)
  File "/usr/local/lib/python3.7/site-packages/sqlalchemy/pool/base.py", line 493, in checkout
    rec = pool._do_get()
  File "/usr/local/lib/python3.7/site-packages/sqlalchemy/pool/impl.py", line 146, in _do_get
    self._dec_overflow()
  File "/usr/local/lib/python3.7/site-packages/sqlalchemy/util/langhelpers.py", line 72, in __exit__
    with_traceback=exc_tb,
  File "/usr/local/lib/python3.7/site-packages/sqlalchemy/util/compat.py", line 211, in raise_
    raise exception
  File "/usr/local/lib/python3.7/site-packages/sqlalchemy/pool/impl.py", line 143, in _do_get
    return self._create_connection()
  File "/usr/local/lib/python3.7/site-packages/sqlalchemy/pool/base.py", line 273, in _create_connection
    return _ConnectionRecord(self)
  File "/usr/local/lib/python3.7/site-packages/sqlalchemy/pool/base.py", line 388, in __init__
    self.__connect()
  File "/usr/local/lib/python3.7/site-packages/sqlalchemy/pool/base.py", line 691, in __connect
    pool.logger.debug("Error on connect(): %s", e)
  File "/usr/local/lib/python3.7/site-packages/sqlalchemy/util/langhelpers.py", line 72, in __exit__
    with_traceback=exc_tb,
  File "/usr/local/lib/python3.7/site-packages/sqlalchemy/util/compat.py", line 211, in raise_
    raise exception
  File "/usr/local/lib/python3.7/site-packages/sqlalchemy/pool/base.py", line 686, in __connect
    self.dbapi_connection = connection = pool._invoke_creator(self)
  File "/usr/local/lib/python3.7/site-packages/sqlalchemy/engine/create.py", line 574, in connect
    return dialect.connect(*cargs, **cparams)
  File "/usr/local/lib/python3.7/site-packages/sqlalchemy/engine/default.py", line 598, in connect
    return self.dbapi.connect(*cargs, **cparams)
  File "/usr/local/lib/python3.7/site-packages/psycopg2/__init__.py", line 122, in connect
    conn = _connect(dsn, connection_factory=connection_factory, **kwasync)
sqlalchemy.exc.OperationalError: (psycopg2.OperationalError) could not translate host name "postgres" to address: Temporary failure in name resolution

(Background on this error at: https://sqlalche.me/e/14/e3q8)
[2023-10-26T07:19:19.529+0000] {processor.py:156} INFO - Started process (PID=455) to work on /opt/airflow/dags/upload_task.py
[2023-10-26T07:19:19.647+0000] {processor.py:758} INFO - Processing file /opt/airflow/dags/upload_task.py for tasks to queue
[2023-10-26T07:19:19.821+0000] {logging_mixin.py:117} INFO - [2023-10-26T07:19:19.763+0000] {dagbag.py:525} INFO - Filling up the DagBag from /opt/airflow/dags/upload_task.py
[2023-10-26T07:19:53.875+0000] {logging_mixin.py:117} INFO - [2023-10-26T07:19:53.330+0000] {timeout.py:68} ERROR - Process timed out, PID: 455
[2023-10-26T07:19:56.171+0000] {logging_mixin.py:117} INFO - [2023-10-26T07:19:54.050+0000] {dagbag.py:330} ERROR - Failed to import: /opt/airflow/dags/upload_task.py
Traceback (most recent call last):
  File "/usr/local/lib/python3.7/site-packages/airflow/models/dagbag.py", line 326, in parse
    loader.exec_module(new_module)
  File "<frozen importlib._bootstrap_external>", line 728, in exec_module
  File "<frozen importlib._bootstrap>", line 219, in _call_with_frames_removed
  File "/opt/airflow/dags/upload_task.py", line 1, in <module>
    from airflow.providers.google.suite.transfers.local_to_drive import LocalFilesystemToGoogleDriveOperator
  File "/usr/local/lib/python3.7/site-packages/airflow/providers/google/suite/transfers/local_to_drive.py", line 26, in <module>
    from airflow.providers.google.suite.hooks.drive import GoogleDriveHook
  File "/usr/local/lib/python3.7/site-packages/airflow/providers/google/suite/hooks/drive.py", line 27, in <module>
    from airflow.providers.google.common.hooks.base_google import GoogleBaseHook
  File "/usr/local/lib/python3.7/site-packages/airflow/providers/google/common/hooks/base_google.py", line 38, in <module>
    from google.api_core.exceptions import Forbidden, ResourceExhausted, TooManyRequests
  File "/usr/local/lib/python3.7/site-packages/google/api_core/exceptions.py", line 29, in <module>
    from google.rpc import error_details_pb2
  File "/usr/local/lib/python3.7/site-packages/google/rpc/error_details_pb2.py", line 20, in <module>
    from google.protobuf import descriptor as _descriptor
  File "/usr/local/lib/python3.7/site-packages/google/protobuf/descriptor.py", line 40, in <module>
    from google.protobuf.internal import api_implementation
  File "/usr/local/lib/python3.7/site-packages/google/protobuf/internal/api_implementation.py", line 74, in <module>
    if _CanImport('google._upb._message'):
  File "/usr/local/lib/python3.7/site-packages/google/protobuf/internal/api_implementation.py", line 64, in _CanImport
    mod = importlib.import_module(mod_name)
  File "/usr/local/lib/python3.7/importlib/__init__.py", line 127, in import_module
    return _bootstrap._gcd_import(name[level:], package, level)
  File "<frozen importlib._bootstrap>", line 978, in _find_and_load
  File "/usr/local/lib/python3.7/site-packages/airflow/utils/timeout.py", line 69, in handle_timeout
    raise AirflowTaskTimeout(self.error_message)
airflow.exceptions.AirflowTaskTimeout: DagBag import timeout for /opt/airflow/dags/upload_task.py after 30.0s.
Please take a look at these docs to improve your DAG import time:
* https://airflow.apache.org/docs/apache-airflow/2.4.0/best-practices.html#top-level-python-code
* https://airflow.apache.org/docs/apache-airflow/2.4.0/best-practices.html#reducing-dag-complexity, PID: 455
[2023-10-26T07:19:56.902+0000] {processor.py:770} WARNING - No viable dags retrieved from /opt/airflow/dags/upload_task.py
[2023-10-26T07:20:38.459+0000] {processor.py:156} INFO - Started process (PID=485) to work on /opt/airflow/dags/upload_task.py
[2023-10-26T07:20:38.462+0000] {processor.py:758} INFO - Processing file /opt/airflow/dags/upload_task.py for tasks to queue
[2023-10-26T07:20:38.470+0000] {logging_mixin.py:117} INFO - [2023-10-26T07:20:38.469+0000] {dagbag.py:525} INFO - Filling up the DagBag from /opt/airflow/dags/upload_task.py
[2023-10-26T07:21:12.593+0000] {logging_mixin.py:117} INFO - [2023-10-26T07:21:09.237+0000] {timeout.py:68} ERROR - Process timed out, PID: 485
[2023-10-26T07:21:46.657+0000] {logging_mixin.py:117} INFO - [2023-10-26T07:21:20.845+0000] {dagbag.py:330} ERROR - Failed to import: /opt/airflow/dags/upload_task.py
Traceback (most recent call last):
  File "/usr/local/lib/python3.7/site-packages/airflow/models/dagbag.py", line 326, in parse
    loader.exec_module(new_module)
  File "<frozen importlib._bootstrap_external>", line 728, in exec_module
  File "<frozen importlib._bootstrap>", line 219, in _call_with_frames_removed
  File "/opt/airflow/dags/upload_task.py", line 1, in <module>
    from airflow.providers.google.suite.transfers.local_to_drive import LocalFilesystemToGoogleDriveOperator
  File "/usr/local/lib/python3.7/site-packages/airflow/providers/google/suite/transfers/local_to_drive.py", line 26, in <module>
    from airflow.providers.google.suite.hooks.drive import GoogleDriveHook
  File "/usr/local/lib/python3.7/site-packages/airflow/providers/google/suite/hooks/drive.py", line 27, in <module>
    from airflow.providers.google.common.hooks.base_google import GoogleBaseHook
  File "/usr/local/lib/python3.7/site-packages/airflow/providers/google/common/hooks/base_google.py", line 51, in <module>
    from airflow.providers.google.cloud.utils.credentials_provider import (
  File "/usr/local/lib/python3.7/site-packages/airflow/providers/google/cloud/utils/credentials_provider.py", line 38, in <module>
    from airflow.providers.google.cloud._internal_client.secret_manager_client import _SecretManagerClient
  File "/usr/local/lib/python3.7/site-packages/airflow/providers/google/cloud/_internal_client/secret_manager_client.py", line 23, in <module>
    from google.cloud.secretmanager_v1 import SecretManagerServiceClient
  File "/usr/local/lib/python3.7/site-packages/google/cloud/secretmanager_v1/__init__.py", line 21, in <module>
    from .services.secret_manager_service import (
  File "/usr/local/lib/python3.7/site-packages/google/cloud/secretmanager_v1/services/secret_manager_service/__init__.py", line 16, in <module>
    from .async_client import SecretManagerServiceAsyncClient
  File "/usr/local/lib/python3.7/site-packages/google/cloud/secretmanager_v1/services/secret_manager_service/async_client.py", line 45, in <module>
    from google.iam.v1 import iam_policy_pb2  # type: ignore
  File "/usr/local/lib/python3.7/site-packages/google/iam/v1/iam_policy_pb2.py", line 32, in <module>
    from google.api import client_pb2 as google_dot_api_dot_client__pb2
  File "/usr/local/lib/python3.7/site-packages/google/api/client_pb2.py", line 32, in <module>
    from google.api import launch_stage_pb2 as google_dot_api_dot_launch__stage__pb2
  File "/usr/local/lib/python3.7/site-packages/google/api/launch_stage_pb2.py", line 33, in <module>
    b"\n\x1dgoogle/api/launch_stage.proto\x12\ngoogle.api*\x8c\x01\n\x0bLaunchStage\x12\x1c\n\x18LAUNCH_STAGE_UNSPECIFIED\x10\x00\x12\x11\n\rUNIMPLEMENTED\x10\x06\x12\r\n\tPRELAUNCH\x10\x07\x12\x10\n\x0c\x45\x41RLY_ACCESS\x10\x01\x12\t\n\x05\x41LPHA\x10\x02\x12\x08\n\x04\x42\x45TA\x10\x03\x12\x06\n\x02GA\x10\x04\x12\x0e\n\nDEPRECATED\x10\x05\x42Z\n\x0e\x63om.google.apiB\x10LaunchStageProtoP\x01Z-google.golang.org/genproto/googleapis/api;api\xa2\x02\x04GAPIb\x06proto3"
  File "/usr/local/lib/python3.7/site-packages/airflow/utils/timeout.py", line 69, in handle_timeout
    raise AirflowTaskTimeout(self.error_message)
airflow.exceptions.AirflowTaskTimeout: DagBag import timeout for /opt/airflow/dags/upload_task.py after 30.0s.
Please take a look at these docs to improve your DAG import time:
* https://airflow.apache.org/docs/apache-airflow/2.4.0/best-practices.html#top-level-python-code
* https://airflow.apache.org/docs/apache-airflow/2.4.0/best-practices.html#reducing-dag-complexity, PID: 485
[2023-10-26T07:21:46.766+0000] {processor.py:770} WARNING - No viable dags retrieved from /opt/airflow/dags/upload_task.py
[2023-10-26T07:21:51.217+0000] {processor.py:156} INFO - Started process (PID=532) to work on /opt/airflow/dags/upload_task.py
[2023-10-26T07:21:51.276+0000] {processor.py:758} INFO - Processing file /opt/airflow/dags/upload_task.py for tasks to queue
[2023-10-26T07:21:51.316+0000] {logging_mixin.py:117} INFO - [2023-10-26T07:21:51.314+0000] {dagbag.py:525} INFO - Filling up the DagBag from /opt/airflow/dags/upload_task.py
[2023-10-26T07:22:23.665+0000] {logging_mixin.py:117} INFO - [2023-10-26T07:22:23.589+0000] {timeout.py:68} ERROR - Process timed out, PID: 532
[2023-10-26T07:22:24.127+0000] {logging_mixin.py:117} INFO - [2023-10-26T07:22:23.666+0000] {dagbag.py:330} ERROR - Failed to import: /opt/airflow/dags/upload_task.py
Traceback (most recent call last):
  File "<frozen importlib._bootstrap_external>", line 1219, in _path_importer_cache
KeyError: '/usr/local/lib/python3.7/site-packages/airflow/hooks'

During handling of the above exception, another exception occurred:

Traceback (most recent call last):
  File "<frozen importlib._bootstrap_external>", line 1197, in _path_hooks
zipimport.ZipImportError: not a Zip file

During handling of the above exception, another exception occurred:

Traceback (most recent call last):
  File "/usr/local/lib/python3.7/site-packages/airflow/models/dagbag.py", line 326, in parse
    loader.exec_module(new_module)
  File "<frozen importlib._bootstrap_external>", line 728, in exec_module
  File "<frozen importlib._bootstrap>", line 219, in _call_with_frames_removed
  File "/opt/airflow/dags/upload_task.py", line 1, in <module>
    from airflow.providers.google.suite.transfers.local_to_drive import LocalFilesystemToGoogleDriveOperator
  File "/usr/local/lib/python3.7/site-packages/airflow/providers/google/suite/transfers/local_to_drive.py", line 26, in <module>
    from airflow.providers.google.suite.hooks.drive import GoogleDriveHook
  File "/usr/local/lib/python3.7/site-packages/airflow/providers/google/suite/hooks/drive.py", line 27, in <module>
    from airflow.providers.google.common.hooks.base_google import GoogleBaseHook
  File "/usr/local/lib/python3.7/site-packages/airflow/providers/google/common/hooks/base_google.py", line 50, in <module>
    from airflow.hooks.base import BaseHook
  File "<frozen importlib._bootstrap>", line 983, in _find_and_load
  File "<frozen importlib._bootstrap>", line 963, in _find_and_load_unlocked
  File "<frozen importlib._bootstrap>", line 906, in _find_spec
  File "<frozen importlib._bootstrap_external>", line 1280, in find_spec
  File "<frozen importlib._bootstrap_external>", line 1249, in _get_spec
  File "<frozen importlib._bootstrap_external>", line 1221, in _path_importer_cache
  File "<frozen importlib._bootstrap_external>", line 1197, in _path_hooks
  File "/usr/local/lib/python3.7/site-packages/airflow/utils/timeout.py", line 69, in handle_timeout
    raise AirflowTaskTimeout(self.error_message)
airflow.exceptions.AirflowTaskTimeout: DagBag import timeout for /opt/airflow/dags/upload_task.py after 30.0s.
Please take a look at these docs to improve your DAG import time:
* https://airflow.apache.org/docs/apache-airflow/2.4.0/best-practices.html#top-level-python-code
* https://airflow.apache.org/docs/apache-airflow/2.4.0/best-practices.html#reducing-dag-complexity, PID: 532
[2023-10-26T07:22:24.138+0000] {processor.py:770} WARNING - No viable dags retrieved from /opt/airflow/dags/upload_task.py
[2023-10-26T07:22:25.690+0000] {processor.py:178} INFO - Processing /opt/airflow/dags/upload_task.py took 34.399 seconds
[2023-10-26T07:23:07.058+0000] {processor.py:156} INFO - Started process (PID=574) to work on /opt/airflow/dags/upload_task.py
[2023-10-26T07:23:07.063+0000] {processor.py:758} INFO - Processing file /opt/airflow/dags/upload_task.py for tasks to queue
[2023-10-26T07:23:07.075+0000] {logging_mixin.py:117} INFO - [2023-10-26T07:23:07.074+0000] {dagbag.py:525} INFO - Filling up the DagBag from /opt/airflow/dags/upload_task.py
[2023-10-26T07:23:10.400+0000] {logging_mixin.py:117} INFO - [2023-10-26T07:23:10.296+0000] {dagbag.py:330} ERROR - Failed to import: /opt/airflow/dags/upload_task.py
Traceback (most recent call last):
  File "/usr/local/lib/python3.7/site-packages/airflow/models/dagbag.py", line 326, in parse
    loader.exec_module(new_module)
  File "<frozen importlib._bootstrap_external>", line 728, in exec_module
  File "<frozen importlib._bootstrap>", line 219, in _call_with_frames_removed
  File "/opt/airflow/dags/upload_task.py", line 19, in <module>
    gcp_conn_id = ""
  File "/usr/local/lib/python3.7/site-packages/airflow/models/baseoperator.py", line 394, in apply_defaults
    raise AirflowException(f"missing keyword arguments {display}")
airflow.exceptions.AirflowException: missing keyword arguments 'drive_folder', 'local_paths'
[2023-10-26T07:23:10.437+0000] {processor.py:770} WARNING - No viable dags retrieved from /opt/airflow/dags/upload_task.py
[2023-10-26T07:23:27.340+0000] {processor.py:181} ERROR - Got an exception! Propagating...
Traceback (most recent call last):
  File "/usr/local/lib/python3.7/site-packages/sqlalchemy/engine/base.py", line 3371, in _wrap_pool_connect
    return fn()
  File "/usr/local/lib/python3.7/site-packages/sqlalchemy/pool/base.py", line 327, in connect
    return _ConnectionFairy._checkout(self)
  File "/usr/local/lib/python3.7/site-packages/sqlalchemy/pool/base.py", line 894, in _checkout
    fairy = _ConnectionRecord.checkout(pool)
  File "/usr/local/lib/python3.7/site-packages/sqlalchemy/pool/base.py", line 493, in checkout
    rec = pool._do_get()
  File "/usr/local/lib/python3.7/site-packages/sqlalchemy/pool/impl.py", line 146, in _do_get
    self._dec_overflow()
  File "/usr/local/lib/python3.7/site-packages/sqlalchemy/util/langhelpers.py", line 72, in __exit__
    with_traceback=exc_tb,
  File "/usr/local/lib/python3.7/site-packages/sqlalchemy/util/compat.py", line 211, in raise_
    raise exception
  File "/usr/local/lib/python3.7/site-packages/sqlalchemy/pool/impl.py", line 143, in _do_get
    return self._create_connection()
  File "/usr/local/lib/python3.7/site-packages/sqlalchemy/pool/base.py", line 273, in _create_connection
    return _ConnectionRecord(self)
  File "/usr/local/lib/python3.7/site-packages/sqlalchemy/pool/base.py", line 388, in __init__
    self.__connect()
  File "/usr/local/lib/python3.7/site-packages/sqlalchemy/pool/base.py", line 691, in __connect
    pool.logger.debug("Error on connect(): %s", e)
  File "/usr/local/lib/python3.7/site-packages/sqlalchemy/util/langhelpers.py", line 72, in __exit__
    with_traceback=exc_tb,
  File "/usr/local/lib/python3.7/site-packages/sqlalchemy/util/compat.py", line 211, in raise_
    raise exception
  File "/usr/local/lib/python3.7/site-packages/sqlalchemy/pool/base.py", line 686, in __connect
    self.dbapi_connection = connection = pool._invoke_creator(self)
  File "/usr/local/lib/python3.7/site-packages/sqlalchemy/engine/create.py", line 574, in connect
    return dialect.connect(*cargs, **cparams)
  File "/usr/local/lib/python3.7/site-packages/sqlalchemy/engine/default.py", line 598, in connect
    return self.dbapi.connect(*cargs, **cparams)
  File "/usr/local/lib/python3.7/site-packages/psycopg2/__init__.py", line 122, in connect
    conn = _connect(dsn, connection_factory=connection_factory, **kwasync)
psycopg2.OperationalError: could not translate host name "postgres" to address: Temporary failure in name resolution


The above exception was the direct cause of the following exception:

Traceback (most recent call last):
  File "/usr/local/lib/python3.7/site-packages/airflow/dag_processing/processor.py", line 177, in _run_file_processor
    _handle_dag_file_processing()
  File "/usr/local/lib/python3.7/site-packages/airflow/dag_processing/processor.py", line 161, in _handle_dag_file_processing
    callback_requests=callback_requests,
  File "/usr/local/lib/python3.7/site-packages/airflow/utils/session.py", line 75, in wrapper
    return func(*args, session=session, **kwargs)
  File "/usr/local/lib/python3.7/site-packages/airflow/dag_processing/processor.py", line 771, in process_file
    self.update_import_errors(session, dagbag)
  File "/usr/local/lib/python3.7/site-packages/airflow/dag_processing/processor.py", line 558, in update_import_errors
    existing_import_error_files = [x.filename for x in session.query(errors.ImportError.filename).all()]
  File "/usr/local/lib/python3.7/site-packages/sqlalchemy/orm/query.py", line 2773, in all
    return self._iter().all()
  File "/usr/local/lib/python3.7/site-packages/sqlalchemy/orm/query.py", line 2919, in _iter
    execution_options={"_sa_orm_load_options": self.load_options},
  File "/usr/local/lib/python3.7/site-packages/sqlalchemy/orm/session.py", line 1716, in execute
    conn = self._connection_for_bind(bind)
  File "/usr/local/lib/python3.7/site-packages/sqlalchemy/orm/session.py", line 1556, in _connection_for_bind
    engine, execution_options
  File "/usr/local/lib/python3.7/site-packages/sqlalchemy/orm/session.py", line 750, in _connection_for_bind
    conn = bind.connect()
  File "/usr/local/lib/python3.7/site-packages/sqlalchemy/engine/base.py", line 3325, in connect
    return self._connection_cls(self, close_with_result=close_with_result)
  File "/usr/local/lib/python3.7/site-packages/sqlalchemy/engine/base.py", line 96, in __init__
    else engine.raw_connection()
  File "/usr/local/lib/python3.7/site-packages/sqlalchemy/engine/base.py", line 3404, in raw_connection
    return self._wrap_pool_connect(self.pool.connect, _connection)
  File "/usr/local/lib/python3.7/site-packages/sqlalchemy/engine/base.py", line 3375, in _wrap_pool_connect
    e, dialect, self
  File "/usr/local/lib/python3.7/site-packages/sqlalchemy/engine/base.py", line 2209, in _handle_dbapi_exception_noconnection
    sqlalchemy_exception, with_traceback=exc_info[2], from_=e
  File "/usr/local/lib/python3.7/site-packages/sqlalchemy/util/compat.py", line 211, in raise_
    raise exception
  File "/usr/local/lib/python3.7/site-packages/sqlalchemy/engine/base.py", line 3371, in _wrap_pool_connect
    return fn()
  File "/usr/local/lib/python3.7/site-packages/sqlalchemy/pool/base.py", line 327, in connect
    return _ConnectionFairy._checkout(self)
  File "/usr/local/lib/python3.7/site-packages/sqlalchemy/pool/base.py", line 894, in _checkout
    fairy = _ConnectionRecord.checkout(pool)
  File "/usr/local/lib/python3.7/site-packages/sqlalchemy/pool/base.py", line 493, in checkout
    rec = pool._do_get()
  File "/usr/local/lib/python3.7/site-packages/sqlalchemy/pool/impl.py", line 146, in _do_get
    self._dec_overflow()
  File "/usr/local/lib/python3.7/site-packages/sqlalchemy/util/langhelpers.py", line 72, in __exit__
    with_traceback=exc_tb,
  File "/usr/local/lib/python3.7/site-packages/sqlalchemy/util/compat.py", line 211, in raise_
    raise exception
  File "/usr/local/lib/python3.7/site-packages/sqlalchemy/pool/impl.py", line 143, in _do_get
    return self._create_connection()
  File "/usr/local/lib/python3.7/site-packages/sqlalchemy/pool/base.py", line 273, in _create_connection
    return _ConnectionRecord(self)
  File "/usr/local/lib/python3.7/site-packages/sqlalchemy/pool/base.py", line 388, in __init__
    self.__connect()
  File "/usr/local/lib/python3.7/site-packages/sqlalchemy/pool/base.py", line 691, in __connect
    pool.logger.debug("Error on connect(): %s", e)
  File "/usr/local/lib/python3.7/site-packages/sqlalchemy/util/langhelpers.py", line 72, in __exit__
    with_traceback=exc_tb,
  File "/usr/local/lib/python3.7/site-packages/sqlalchemy/util/compat.py", line 211, in raise_
    raise exception
  File "/usr/local/lib/python3.7/site-packages/sqlalchemy/pool/base.py", line 686, in __connect
    self.dbapi_connection = connection = pool._invoke_creator(self)
  File "/usr/local/lib/python3.7/site-packages/sqlalchemy/engine/create.py", line 574, in connect
    return dialect.connect(*cargs, **cparams)
  File "/usr/local/lib/python3.7/site-packages/sqlalchemy/engine/default.py", line 598, in connect
    return self.dbapi.connect(*cargs, **cparams)
  File "/usr/local/lib/python3.7/site-packages/psycopg2/__init__.py", line 122, in connect
    conn = _connect(dsn, connection_factory=connection_factory, **kwasync)
sqlalchemy.exc.OperationalError: (psycopg2.OperationalError) could not translate host name "postgres" to address: Temporary failure in name resolution

(Background on this error at: https://sqlalche.me/e/14/e3q8)
[2023-10-26T07:24:37.332+0000] {processor.py:156} INFO - Started process (PID=616) to work on /opt/airflow/dags/upload_task.py
[2023-10-26T07:24:37.335+0000] {processor.py:758} INFO - Processing file /opt/airflow/dags/upload_task.py for tasks to queue
[2023-10-26T07:24:37.348+0000] {logging_mixin.py:117} INFO - [2023-10-26T07:24:37.347+0000] {dagbag.py:525} INFO - Filling up the DagBag from /opt/airflow/dags/upload_task.py
[2023-10-26T07:24:46.945+0000] {logging_mixin.py:117} INFO - [2023-10-26T07:24:46.917+0000] {dagbag.py:330} ERROR - Failed to import: /opt/airflow/dags/upload_task.py
Traceback (most recent call last):
  File "/usr/local/lib/python3.7/site-packages/airflow/models/dagbag.py", line 326, in parse
    loader.exec_module(new_module)
  File "<frozen importlib._bootstrap_external>", line 728, in exec_module
  File "<frozen importlib._bootstrap>", line 219, in _call_with_frames_removed
  File "/opt/airflow/dags/upload_task.py", line 19, in <module>
    gcp_conn_id = ""
  File "/usr/local/lib/python3.7/site-packages/airflow/models/baseoperator.py", line 394, in apply_defaults
    raise AirflowException(f"missing keyword arguments {display}")
airflow.exceptions.AirflowException: missing keyword arguments 'drive_folder', 'local_paths'
[2023-10-26T07:24:46.962+0000] {processor.py:770} WARNING - No viable dags retrieved from /opt/airflow/dags/upload_task.py
[2023-10-26T07:24:57.000+0000] {processor.py:181} ERROR - Got an exception! Propagating...
Traceback (most recent call last):
  File "/usr/local/lib/python3.7/site-packages/sqlalchemy/engine/base.py", line 3371, in _wrap_pool_connect
    return fn()
  File "/usr/local/lib/python3.7/site-packages/sqlalchemy/pool/base.py", line 327, in connect
    return _ConnectionFairy._checkout(self)
  File "/usr/local/lib/python3.7/site-packages/sqlalchemy/pool/base.py", line 894, in _checkout
    fairy = _ConnectionRecord.checkout(pool)
  File "/usr/local/lib/python3.7/site-packages/sqlalchemy/pool/base.py", line 493, in checkout
    rec = pool._do_get()
  File "/usr/local/lib/python3.7/site-packages/sqlalchemy/pool/impl.py", line 146, in _do_get
    self._dec_overflow()
  File "/usr/local/lib/python3.7/site-packages/sqlalchemy/util/langhelpers.py", line 72, in __exit__
    with_traceback=exc_tb,
  File "/usr/local/lib/python3.7/site-packages/sqlalchemy/util/compat.py", line 211, in raise_
    raise exception
  File "/usr/local/lib/python3.7/site-packages/sqlalchemy/pool/impl.py", line 143, in _do_get
    return self._create_connection()
  File "/usr/local/lib/python3.7/site-packages/sqlalchemy/pool/base.py", line 273, in _create_connection
    return _ConnectionRecord(self)
  File "/usr/local/lib/python3.7/site-packages/sqlalchemy/pool/base.py", line 388, in __init__
    self.__connect()
  File "/usr/local/lib/python3.7/site-packages/sqlalchemy/pool/base.py", line 691, in __connect
    pool.logger.debug("Error on connect(): %s", e)
  File "/usr/local/lib/python3.7/site-packages/sqlalchemy/util/langhelpers.py", line 72, in __exit__
    with_traceback=exc_tb,
  File "/usr/local/lib/python3.7/site-packages/sqlalchemy/util/compat.py", line 211, in raise_
    raise exception
  File "/usr/local/lib/python3.7/site-packages/sqlalchemy/pool/base.py", line 686, in __connect
    self.dbapi_connection = connection = pool._invoke_creator(self)
  File "/usr/local/lib/python3.7/site-packages/sqlalchemy/engine/create.py", line 574, in connect
    return dialect.connect(*cargs, **cparams)
  File "/usr/local/lib/python3.7/site-packages/sqlalchemy/engine/default.py", line 598, in connect
    return self.dbapi.connect(*cargs, **cparams)
  File "/usr/local/lib/python3.7/site-packages/psycopg2/__init__.py", line 122, in connect
    conn = _connect(dsn, connection_factory=connection_factory, **kwasync)
psycopg2.OperationalError: could not translate host name "postgres" to address: Temporary failure in name resolution


The above exception was the direct cause of the following exception:

Traceback (most recent call last):
  File "/usr/local/lib/python3.7/site-packages/airflow/dag_processing/processor.py", line 177, in _run_file_processor
    _handle_dag_file_processing()
  File "/usr/local/lib/python3.7/site-packages/airflow/dag_processing/processor.py", line 161, in _handle_dag_file_processing
    callback_requests=callback_requests,
  File "/usr/local/lib/python3.7/site-packages/airflow/utils/session.py", line 75, in wrapper
    return func(*args, session=session, **kwargs)
  File "/usr/local/lib/python3.7/site-packages/airflow/dag_processing/processor.py", line 771, in process_file
    self.update_import_errors(session, dagbag)
  File "/usr/local/lib/python3.7/site-packages/airflow/dag_processing/processor.py", line 558, in update_import_errors
    existing_import_error_files = [x.filename for x in session.query(errors.ImportError.filename).all()]
  File "/usr/local/lib/python3.7/site-packages/sqlalchemy/orm/query.py", line 2773, in all
    return self._iter().all()
  File "/usr/local/lib/python3.7/site-packages/sqlalchemy/orm/query.py", line 2919, in _iter
    execution_options={"_sa_orm_load_options": self.load_options},
  File "/usr/local/lib/python3.7/site-packages/sqlalchemy/orm/session.py", line 1716, in execute
    conn = self._connection_for_bind(bind)
  File "/usr/local/lib/python3.7/site-packages/sqlalchemy/orm/session.py", line 1556, in _connection_for_bind
    engine, execution_options
  File "/usr/local/lib/python3.7/site-packages/sqlalchemy/orm/session.py", line 750, in _connection_for_bind
    conn = bind.connect()
  File "/usr/local/lib/python3.7/site-packages/sqlalchemy/engine/base.py", line 3325, in connect
    return self._connection_cls(self, close_with_result=close_with_result)
  File "/usr/local/lib/python3.7/site-packages/sqlalchemy/engine/base.py", line 96, in __init__
    else engine.raw_connection()
  File "/usr/local/lib/python3.7/site-packages/sqlalchemy/engine/base.py", line 3404, in raw_connection
    return self._wrap_pool_connect(self.pool.connect, _connection)
  File "/usr/local/lib/python3.7/site-packages/sqlalchemy/engine/base.py", line 3375, in _wrap_pool_connect
    e, dialect, self
  File "/usr/local/lib/python3.7/site-packages/sqlalchemy/engine/base.py", line 2209, in _handle_dbapi_exception_noconnection
    sqlalchemy_exception, with_traceback=exc_info[2], from_=e
  File "/usr/local/lib/python3.7/site-packages/sqlalchemy/util/compat.py", line 211, in raise_
    raise exception
  File "/usr/local/lib/python3.7/site-packages/sqlalchemy/engine/base.py", line 3371, in _wrap_pool_connect
    return fn()
  File "/usr/local/lib/python3.7/site-packages/sqlalchemy/pool/base.py", line 327, in connect
    return _ConnectionFairy._checkout(self)
  File "/usr/local/lib/python3.7/site-packages/sqlalchemy/pool/base.py", line 894, in _checkout
    fairy = _ConnectionRecord.checkout(pool)
  File "/usr/local/lib/python3.7/site-packages/sqlalchemy/pool/base.py", line 493, in checkout
    rec = pool._do_get()
  File "/usr/local/lib/python3.7/site-packages/sqlalchemy/pool/impl.py", line 146, in _do_get
    self._dec_overflow()
  File "/usr/local/lib/python3.7/site-packages/sqlalchemy/util/langhelpers.py", line 72, in __exit__
    with_traceback=exc_tb,
  File "/usr/local/lib/python3.7/site-packages/sqlalchemy/util/compat.py", line 211, in raise_
    raise exception
  File "/usr/local/lib/python3.7/site-packages/sqlalchemy/pool/impl.py", line 143, in _do_get
    return self._create_connection()
  File "/usr/local/lib/python3.7/site-packages/sqlalchemy/pool/base.py", line 273, in _create_connection
    return _ConnectionRecord(self)
  File "/usr/local/lib/python3.7/site-packages/sqlalchemy/pool/base.py", line 388, in __init__
    self.__connect()
  File "/usr/local/lib/python3.7/site-packages/sqlalchemy/pool/base.py", line 691, in __connect
    pool.logger.debug("Error on connect(): %s", e)
  File "/usr/local/lib/python3.7/site-packages/sqlalchemy/util/langhelpers.py", line 72, in __exit__
    with_traceback=exc_tb,
  File "/usr/local/lib/python3.7/site-packages/sqlalchemy/util/compat.py", line 211, in raise_
    raise exception
  File "/usr/local/lib/python3.7/site-packages/sqlalchemy/pool/base.py", line 686, in __connect
    self.dbapi_connection = connection = pool._invoke_creator(self)
  File "/usr/local/lib/python3.7/site-packages/sqlalchemy/engine/create.py", line 574, in connect
    return dialect.connect(*cargs, **cparams)
  File "/usr/local/lib/python3.7/site-packages/sqlalchemy/engine/default.py", line 598, in connect
    return self.dbapi.connect(*cargs, **cparams)
  File "/usr/local/lib/python3.7/site-packages/psycopg2/__init__.py", line 122, in connect
    conn = _connect(dsn, connection_factory=connection_factory, **kwasync)
sqlalchemy.exc.OperationalError: (psycopg2.OperationalError) could not translate host name "postgres" to address: Temporary failure in name resolution

(Background on this error at: https://sqlalche.me/e/14/e3q8)
[2023-10-26T07:25:51.022+0000] {processor.py:156} INFO - Started process (PID=27) to work on /opt/airflow/dags/upload_task.py
[2023-10-26T07:25:51.024+0000] {processor.py:758} INFO - Processing file /opt/airflow/dags/upload_task.py for tasks to queue
[2023-10-26T07:25:51.026+0000] {logging_mixin.py:117} INFO - [2023-10-26T07:25:51.025+0000] {dagbag.py:525} INFO - Filling up the DagBag from /opt/airflow/dags/upload_task.py
[2023-10-26T07:25:51.679+0000] {logging_mixin.py:117} INFO - [2023-10-26T07:25:51.667+0000] {dagbag.py:330} ERROR - Failed to import: /opt/airflow/dags/upload_task.py
Traceback (most recent call last):
  File "/usr/local/lib/python3.7/site-packages/airflow/models/dagbag.py", line 326, in parse
    loader.exec_module(new_module)
  File "<frozen importlib._bootstrap_external>", line 728, in exec_module
  File "<frozen importlib._bootstrap>", line 219, in _call_with_frames_removed
  File "/opt/airflow/dags/upload_task.py", line 19, in <module>
    gcp_conn_id = ""
  File "/usr/local/lib/python3.7/site-packages/airflow/models/baseoperator.py", line 394, in apply_defaults
    raise AirflowException(f"missing keyword arguments {display}")
airflow.exceptions.AirflowException: missing keyword arguments 'drive_folder', 'local_paths'
[2023-10-26T07:25:51.684+0000] {processor.py:770} WARNING - No viable dags retrieved from /opt/airflow/dags/upload_task.py
[2023-10-26T07:25:51.787+0000] {processor.py:178} INFO - Processing /opt/airflow/dags/upload_task.py took 0.769 seconds
[2023-10-26T07:26:42.363+0000] {processor.py:156} INFO - Started process (PID=115) to work on /opt/airflow/dags/upload_task.py
[2023-10-26T07:26:42.365+0000] {processor.py:758} INFO - Processing file /opt/airflow/dags/upload_task.py for tasks to queue
[2023-10-26T07:26:42.367+0000] {logging_mixin.py:117} INFO - [2023-10-26T07:26:42.366+0000] {dagbag.py:525} INFO - Filling up the DagBag from /opt/airflow/dags/upload_task.py
[2023-10-26T07:26:43.630+0000] {logging_mixin.py:117} INFO - [2023-10-26T07:26:43.599+0000] {dagbag.py:330} ERROR - Failed to import: /opt/airflow/dags/upload_task.py
Traceback (most recent call last):
  File "/usr/local/lib/python3.7/site-packages/airflow/models/dagbag.py", line 326, in parse
    loader.exec_module(new_module)
  File "<frozen importlib._bootstrap_external>", line 728, in exec_module
  File "<frozen importlib._bootstrap>", line 219, in _call_with_frames_removed
  File "/opt/airflow/dags/upload_task.py", line 19, in <module>
    gcp_conn_id = ""
  File "/usr/local/lib/python3.7/site-packages/airflow/models/baseoperator.py", line 394, in apply_defaults
    raise AirflowException(f"missing keyword arguments {display}")
airflow.exceptions.AirflowException: missing keyword arguments 'drive_folder', 'local_paths'
[2023-10-26T07:26:43.647+0000] {processor.py:770} WARNING - No viable dags retrieved from /opt/airflow/dags/upload_task.py
[2023-10-26T07:26:46.658+0000] {processor.py:178} INFO - Processing /opt/airflow/dags/upload_task.py took 4.302 seconds
